Workbook

Sheet Quick Setup
A1: Rounding | C1: Make a copy (for google drive; recommended) or download this spreadsheet (for other spreadsheet programs). Do not request editing access
A2: 2.5
C4: Main Lifts | D4: Maxes | E4: Single @8 percentage | I4: When above or below rep target
C5: Squat | D5: 490 | E5: 0.9 | H5: Sets | I5: Below rep target by 2+ reps | J5: Below rep target by 1 rep | K5: Hit rep target | L5: Beat by 1 rep | M5: Beat by 2 reps | N5: Beat by 3 reps | O5: Beat by 4 reps | P5: Beat by 5+ reps
C6: Bench Press | D6: 325 | E6: 0.9 | G6: =C5 -> Squat | H6: 5 | I6: -0.05 | J6: -0.02 | K6: 0 | L6: 0.005 | M6: 0.01 | N6: 0.015 | O6: 0.02 | P6: 0.03
B7: Primary stance | C7: Deadlift | D7: 525 | E7: 0.9 | G7: =C6 -> Bench Press | H7: 5 | I7: -0.05 | J7: -0.02 | K7: 0 | L7: 0.005 | M7: 0.01 | N7: 0.015 | O7: 0.02 | P7: 0.03
C8: OHP | D8: 200 | E8: 0.9 | G8: =C7 -> Deadlift | H8: 5 | I8: -0.05 | J8: -0.02 | K8: 0 | L8: 0.005 | M8: 0.01 | N8: 0.015 | O8: 0.02 | P8: 0.03
G9: =C8 -> OHP | H9: 5 | I9: -0.05 | J9: -0.02 | K9: 0 | L9: 0.005 | M9: 0.01 | N9: 0.015 | O9: 0.02 | P9: 0.03
C10: Variations: Note - if you don't know your max, you can estimate it. When in doubt, estimate low to start with | D10: Maxes | G10: =C11 -> Front Squat | H10: 5 | I10: -0.05 | J10: -0.02 | K10: 0 | L10: 0.005 | M10: 0.01 | N10: 0.015 | O10: 0.02 | P10: 0.03
B11: Squat auxiliary 1 | C11: Front Squat | D11: 420 | E11: 0.9 | G11: =C12 -> Paused Squat | H11: 5 | I11: -0.05 | J11: -0.02 | K11: 0 | L11: 0.005 | M11: 0.01 | N11: 0.015 | O11: 0.02 | P11: 0.03
B12: Squat auxiliary 2 | C12: Paused Squat | D12: 460 | E12: 0.9 | G12: =C13 -> Close Grip Bench | H12: 5 | I12: -0.05 | J12: -0.02 | K12: 0 | L12: 0.005 | M12: 0.01 | N12: 0.015 | O12: 0.02 | P12: 0.03
B13: Bench auxiliary 1 | C13: Close Grip Bench | D13: 310 | E13: 0.9 | G13: =C14 -> Incline Press | H13: 5 | I13: -0.05 | J13: -0.02 | K13: 0 | L13: 0.005 | M13: 0.01 | N13: 0.015 | O13: 0.02 | P13: 0.03
B14: Bench auxiliary 2 | C14: Incline Press | D14: 280 | E14: 0.9 | G14: =C15 -> Sumo Deadlift | H14: 5 | I14: -0.05 | J14: -0.02 | K14: 0 | L14: 0.005 | M14: 0.01 | N14: 0.015 | O14: 0.02 | P14: 0.03
B15: Deadlift auxiliary | C15: Sumo Deadlift | D15: 500 | E15: 0.9 | G15: =C16 -> Push Press | H15: 5 | I15: -0.05 | J15: -0.02 | K15: 0 | L15: 0.005 | M15: 0.01 | N15: 0.015 | O15: 0.02 | P15: 0.03
B16: OHP auxiliary | C16: Push Press | D16: 245 | E16: 0.9
B18: Back exercises
B19: Barbell rows
B20: DB rows
B21: Chest supported rows
B22: T-bar rows
B23: Pull-ups
B24: Chin-ups
B25: Neutral grip pull-ups
B26: Pull-downs
C30: Normal set rep target
C31: 0.5 | D31: 0.525 | E31: 0.55 | F31: 0.575 | G31: 0.6 | H31: 0.625 | I31: 0.65 | J31: 0.675 | K31: 0.7 | L31: 0.725 | M31: 0.75 | N31: 0.775 | O31: 0.8 | P31: 0.825 | Q31: 0.85 | R31: 0.875 | S31: 0.9 | T31: 0.925 | U31: 0.95 | V31: 0.975 | W31: 1
B32: ='Quick Setup'!C5 -> Squat | C32: 8 | D32: 8 | E32: 8 | F32: 8 | G32: 7 | H32: 7 | I32: 6 | J32: 6 | K32: 5 | L32: 5 | M32: 4 | N32: 4 | O32: 3 | P32: 3 | Q32: 2 | R32: 2 | S32: 1 | T32: 1 | U32: 1 | V32: 1 | W32: 1
B33: ='Quick Setup'!C6 -> Bench Press | C33: =C32 -> 8 | D33: =D32 -> 8 | E33: =E32 -> 8 | F33: =F32 -> 8 | G33: =G32 -> 7 | H33: =H32 -> 7 | I33: =I32 -> 6 | J33: =J32 -> 6 | ... W33: =W32 -> 1
B34: ='Quick Setup'!C7 -> Deadlift | C34: =C33 -> 8 | D34: =D33 -> 8 | E34: =E33 -> 8 | F34: =F33 -> 8 | G34: =G33 -> 7 | H34: =H33 -> 7 | I34: =I33 -> 6 | J34: =J33 -> 6 | ... W34: =W33 -> 1
B35: ='Quick Setup'!C8 -> OHP | C35: =C34 -> 8 | D35: =D34 -> 8 | E35: =E34 -> 8 | F35: =F34 -> 8 | G35: =G34 -> 7 | H35: =H34 -> 7 | I35: =I34 -> 6 | J35: =J34 -> 6 | ... W35: =W34 -> 1
B36: ='Quick Setup'!C11 -> Front Squat | C36: =C35 -> 8 | D36: =D35 -> 8 | E36: =E35 -> 8 | F36: =F35 -> 8 | G36: =G35 -> 7 | H36: =H35 -> 7 | I36: =I35 -> 6 | J36: =J35 -> 6 | ... W36: =W35 -> 1
B37: ='Quick Setup'!C12 -> Paused Squat | C37: =C36 -> 8 | D37: =D36 -> 8 | E37: =E36 -> 8 | F37: =F36 -> 8 | G37: =G36 -> 7 | H37: =H36 -> 7 | I37: =I36 -> 6 | J37: =J36 -> 6 | ... W37: =W36 -> 1
B38: ='Quick Setup'!C13 -> Close Grip Bench | C38: =C37 -> 8 | D38: =D37 -> 8 | E38: =E37 -> 8 | F38: =F37 -> 8 | G38: =G37 -> 7 | H38: =H37 -> 7 | I38: =I37 -> 6 | J38: =J37 -> 6 | ... W38: =W37 -> 1
B39: ='Quick Setup'!C14 -> Incline Press | C39: =C38 -> 8 | D39: =D38 -> 8 | E39: =E38 -> 8 | F39: =F38 -> 8 | G39: =G38 -> 7 | H39: =H38 -> 7 | I39: =I38 -> 6 | J39: =J38 -> 6 | ... W39: =W38 -> 1
B40: ='Quick Setup'!C15 -> Sumo Deadlift | C40: =C39 -> 8 | D40: =D39 -> 8 | E40: =E39 -> 8 | F40: =F39 -> 8 | G40: =G39 -> 7 | H40: =H39 -> 7 | I40: =I39 -> 6 | J40: =J39 -> 6 | ... W40: =W39 -> 1
B41: ='Quick Setup'!C16 -> Push Press | C41: =C40 -> 8 | D41: =D40 -> 8 | E41: =E40 -> 8 | F41: =F40 -> 8 | G41: =G40 -> 7 | H41: =H40 -> 7 | I41: =I40 -> 6 | J41: =J40 -> 6 | ... W41: =W40 -> 1
C44: Last set rep target
C45: 0.5 | D45: 0.525 | E45: 0.55 | F45: 0.575 | G45: 0.6 | H45: 0.625 | I45: 0.65 | J45: 0.675 | K45: 0.7 | L45: 0.725 | M45: 0.75 | N45: 0.775 | O45: 0.8 | P45: 0.825 | Q45: 0.85 | R45: 0.875 | S45: 0.9 | T45: 0.925 | U45: 0.95 | V45: 0.975 | W45: 1
B46: ='Quick Setup'!C5 -> Squat | C46: 18 | D46: 17 | E46: 16 | F46: 15 | G46: 14 | H46: 13 | I46: 12 | J46: 11 | K46: 10 | L46: 9 | M46: 8 | N46: 7 | O46: 6 | P46: 5 | Q46: 4 | R46: 3 | S46: 2 | T46: 2 | U46: 1 | V46: 1 | W46: 1
B47: ='Quick Setup'!C6 -> Bench Press | C47: =C46 -> 18 | D47: =D46 -> 17 | E47: =E46 -> 16 | F47: =F46 -> 15 | G47: =G46 -> 14 | H47: =H46 -> 13 | I47: =I46 -> 12 | J47: =J46 -> 11 | ... W47: =W46 -> 1
...

Sheet Setup
A1: Week | B1: 1 | N1: =B1+1 -> 2 | Z1: =N1+1 -> 3 | AL1: =Z1+1 -> 4 | AX1: =AL1+1 -> 5 | BJ1: =AX1+1 -> 6 | BV1: =BJ1+1 -> 7 | CH1: =BV1+1 -> 8 | CT1: =CH1+1 -> 9 | DF1: =CT1+1 -> 10 | DR1: =DF1+1 -> 11 | ED1: =DR1+1 -> 12 | EP1: =ED1+1 -> 13 | FB1: =EP1+1 -> 14 | FN1: =FB1+1 -> 15 | FZ1: =FN1+1 -> 16 | GL1: =FZ1+1 -> 17 | GX1: =GL1+1 -> 18 | HJ1: =GX1+1 -> 19 | HV1: =HJ1+1 -> 20 | IH1: =HV1+1 -> 21
A2: Lift | B2: Intensity | C2: Reps per normal set | D2: Rep out target | E2: Sets | F2: Below rep target by 2+ reps | G2: Below rep target by 1 rep | H2: Hit rep target | I2: Beat by 1 rep | J2: Beat by 2 reps | K2: Beat by 3 reps | L2: Beat by 4 reps | M2: Beat by 5+ reps | N2: Intensity | O2: Reps per normal set | P2: Rep out target | Q2: Sets | R2: Below rep target by 2+ reps | S2: Below rep target by 1 rep | T2: Hit rep target | U2: Beat by 1 rep | V2: Beat by 2 reps | W2: Beat by 3 reps | X2: Beat by 4 reps | Y2: Beat by 5+ reps | Z2: Intensity | AA2: Reps per normal set | AB2: Rep out target | AC2: Sets | AD2: Below rep target by 2+ reps | AE2: Below rep target by 1 rep | AF2: Hit rep target | AG2: Beat by 1 rep | AH2: Beat by 2 reps | AI2: Beat by 3 reps | AJ2: Beat by 4 reps | AK2: Beat by 5+ reps | AL2: Intensity | AM2: Reps per normal set | AN2: Rep out target | AO2: Sets | AP2: Below rep target by 2+ reps | AQ2: Below rep target by 1 rep | AR2: Hit rep target | AS2: Beat by 1 rep | AT2: Beat by 2 reps | AU2: Beat by 3 reps | AV2: Beat by 4 reps | AW2: Beat by 5+ reps | AX2: Intensity | AY2: Reps per normal set | AZ2: Rep out target | BA2: Sets | BB2: Below rep target by 2+ reps | BC2: Below rep target by 1 rep | BD2: Hit rep target | BE2: Beat by 1 rep | BF2: Beat by 2 reps | BG2: Beat by 3 reps | BH2: Beat by 4 reps | BI2: Beat by 5+ reps | BJ2: Intensity | BK2: Reps per normal set | BL2: Rep out target | BM2: Sets | BN2: Below rep target by 2+ reps | BO2: Below rep target by 1 rep | BP2: Hit rep target | BQ2: Beat by 1 rep | BR2: Beat by 2 reps | BS2: Beat by 3 reps | BT2: Beat by 4 reps | BU2: Beat by 5+ reps | BV2: Intensity | BW2: Reps per normal set | BX2: Rep out target | BY2: Sets | BZ2: Below rep target by 2+ reps | CA2: Below rep target by 1 rep | CB2: Hit rep target | CC2: Beat by 1 rep | CD2: Beat by 2 reps | CE2: Beat by 3 reps | CF2: Beat by 4 reps | CG2: Beat by 5+ reps | CH2: Intensity | CI2: Reps per normal set | CJ2: Rep out target | CK2: Sets | CL2: Below rep target by 2+ reps | CM2: Below rep target by 1 rep | CN2: Hit rep target | CO2: Beat by 1 rep | CP2: Beat by 2 reps | CQ2: Beat by 3 reps | CR2: Beat by 4 reps | CS2: Beat by 5+ reps | CT2: Intensity | CU2: Reps per normal set | CV2: Rep out target | CW2: Sets | CX2: Below rep target by 2+ reps | CY2: Below rep target by 1 rep | CZ2: Hit rep target | DA2: Beat by 1 rep | DB2: Beat by 2 reps | DC2: Beat by 3 reps | DD2: Beat by 4 reps | DE2: Beat by 5+ reps | DF2: Intensity | DG2: Reps per normal set | DH2: Rep out target | DI2: Sets | DJ2: Below rep target by 2+ reps | DK2: Below rep target by 1 rep | DL2: Hit rep target | DM2: Beat by 1 rep | DN2: Beat by 2 reps | DO2: Beat by 3 reps | DP2: Beat by 4 reps | DQ2: Beat by 5+ reps | DR2: Intensity | DS2: Reps per normal set | DT2: Rep out target | DU2: Sets | DV2: Below rep target by 2+ reps | DW2: Below rep target by 1 rep | DX2: Hit rep target | DY2: Beat by 1 rep | DZ2: Beat by 2 reps | EA2: Beat by 3 reps | EB2: Beat by 4 reps | EC2: Beat by 5+ reps | ED2: Intensity | EE2: Reps per normal set | EF2: Rep out target | EG2: Sets | EH2: Below rep target by 2+ reps | EI2: Below rep target by 1 rep | EJ2: Hit rep target | EK2: Beat by 1 rep | EL2: Beat by 2 reps | EM2: Beat by 3 reps | EN2: Beat by 4 reps | EO2: Beat by 5+ reps | EP2: Intensity | EQ2: Reps per normal set | ER2: Rep out target | ES2: Sets | ET2: Below rep target by 2+ reps | EU2: Below rep target by 1 rep | EV2: Hit rep target | EW2: Beat by 1 rep | EX2: Beat by 2 reps | EY2: Beat by 3 reps | EZ2: Beat by 4 reps | FA2: Beat by 5+ reps | FB2: Intensity | FC2: Reps per normal set | FD2: Rep out target | FE2: Sets | FF2: Below rep target by 2+ reps | FG2: Below rep target by 1 rep | FH2: Hit rep target | FI2: Beat by 1 rep | FJ2: Beat by 2 reps | FK2: Beat by 3 reps | FL2: Beat by 4 reps | FM2: Beat by 5+ reps | FN2: Intensity | FO2: Reps per normal set | FP2: Rep out target | FQ2: Sets | FR2: Below rep target by 2+ reps | FS2: Below rep target by 1 rep | FT2: Hit rep target | FU2: Beat by 1 rep | FV2: Beat by 2 reps | FW2: Beat by 3 reps | FX2: Beat by 4 reps | FY2: Beat by 5+ reps | FZ2: Intensity | GA2: Reps per normal set | GB2: Rep out target | GC2: Sets | GD2: Below rep target by 2+ reps | GE2: Below rep target by 1 rep | GF2: Hit rep target | GG2: Beat by 1 rep | GH2: Beat by 2 reps | GI2: Beat by 3 reps | GJ2: Beat by 4 reps | GK2: Beat by 5+ reps | GL2: Intensity | GM2: Reps per normal set | GN2: Rep out target | GO2: Sets | GP2: Below rep target by 2+ reps | GQ2: Below rep target by 1 rep | GR2: Hit rep target | GS2: Beat by 1 rep | GT2: Beat by 2 reps | GU2: Beat by 3 reps | GV2: Beat by 4 reps | GW2: Beat by 5+ reps | GX2: Intensity | GY2: Reps per normal set | GZ2: Rep out target | HA2: Sets | HB2: Below rep target by 2+ reps | HC2: Below rep target by 1 rep | HD2: Hit rep target | HE2: Beat by 1 rep | HF2: Beat by 2 reps | HG2: Beat by 3 reps | HH2: Beat by 4 reps | HI2: Beat by 5+ reps | HJ2: Intensity | HK2: Reps per normal set | HL2: Rep out target | HM2: Sets | HN2: Below rep target by 2+ reps | HO2: Below rep target by 1 rep | HP2: Hit rep target | HQ2: Beat by 1 rep | HR2: Beat by 2 reps | HS2: Beat by 3 reps | HT2: Beat by 4 reps | HU2: Beat by 5+ reps | HV2: Intensity | HW2: Reps per normal set | HX2: Rep out target | HY2: Sets | HZ2: Below rep target by 2+ reps | IA2: Below rep target by 1 rep | IB2: Hit rep target | IC2: Beat by 1 rep | ID2: Beat by 2 reps | IE2: Beat by 3 reps | IF2: Beat by 4 reps | IG2: Beat by 5+ reps | IH2: Intensity | II2: Reps per normal set | IJ2: Rep out target | IK2: Sets | IL2: Below rep target by 2+ reps | IM2: Below rep target by 1 rep | IN2: Hit rep target | IO2: Beat by 1 rep | IP2: Beat by 2 reps | IQ2: Beat by 3 reps | IR2: Beat by 4 reps | IS2: Beat by 5+ reps
A3: ='Quick Setup'!C5 -> Squat | B3: ='Quick Setup'!C60 -> 0.7 | C3: =if(B3='Quick Setup'!$C$31,'Quick Setup'!$C32,if(B3='Quick Setup'!$D$31,'Quick Setup'!$D32,if(B3='Quick Setup'!$E$31,'Quick Setup'!$E32,if(B3='Quick Setup'!$F$31,'Quick Setup'!$F32,if(B3='Quick Setup'!$G$31,'Quick Setup'!$G32,if(B3='Quick Setup'!$H$31,'Quick Setup'!$H32,if(B3='Quick Setup'!$I$31,'Quick Setup'!$I32,if(B3='Quick Setup'!$J$31,'Quick Setup'!$J32,if(B3='Quick Setup'!$K$31,'Quick Setup'!$K32,if(B3='Quick Setup'!$L$31,'Quick Setup'!$L32,if(B3='Quick Setup'!$M$31,'Quick Setup'!$M32,if(B3='Quick Setup'!$N$31,'Quick Setup'!$N32,if(B3='Quick Setup'!$O$31,'Quick Setup'!$O32,if(B3='Quick Setup'!$P$31,'Quick Setup'!$P32,if(B3='Quick Setup'!$Q$31,'Quick Setup'!$Q32,if(B3='Quick Setup'!$R$31,'Quick Setup'!$R32,if(B3='Quick Setup'!$S$31,'Quick Setup'!$S32,if(B3='Quick Setup'!$T$31,'Quick Setup'!$T32,if(B3='Quick Setup'!$U$31,'Quick Setup'!$U32,if(B3='Quick Setup'!$V$31,'Quick Setup'!$V32,'Quick Setup'!$W32)))))))))))))))))))) -> 5 | D3: =if(B3='Quick Setup'!$C$45,'Quick Setup'!$C46,if(B3='Quick Setup'!$D$45,'Quick Setup'!$D46,if(B3='Quick Setup'!$E$45,'Quick Setup'!$E46,if(B3='Quick Setup'!$F$45,'Quick Setup'!$F46,if(B3='Quick Setup'!$G$45,'Quick Setup'!$G46,if(B3='Quick Setup'!$H$45,'Quick Setup'!$H46,if(B3='Quick Setup'!$I$45,'Quick Setup'!$I46,if(B3='Quick Setup'!$J$45,'Quick Setup'!$J46,if(B3='Quick Setup'!$K$45,'Quick Setup'!$K46,if(B3='Quick Setup'!$L$45,'Quick Setup'!$L46,if(B3='Quick Setup'!$M$45,'Quick Setup'!$M46,if(B3='Quick Setup'!$N$45,'Quick Setup'!$N46,if(B3='Quick Setup'!$O$45,'Quick Setup'!$O46,if(B3='Quick Setup'!$P$45,'Quick Setup'!$P46,if(B3='Quick Setup'!$Q$45,'Quick Setup'!$Q46,if(B3='Quick Setup'!$R$45,'Quick Setup'!$R46,if(B3='Quick Setup'!$S$45,'Quick Setup'!$S46,if(B3='Quick Setup'!$T$45,'Quick Setup'!$T46,if(B3='Quick Setup'!$U$45,'Quick Setup'!$U46,if(B3='Quick Setup'!$V$45,'Quick Setup'!$V46,'Quick Setup'!$W46)))))))))))))))))))) -> 10 | E3: ='Quick Setup'!H6 -> 5 | F3: ='Quick Setup'!I6 -> -0.05 | G3: ='Quick Setup'!J6 -> -0.02 | H3: ='Quick Setup'!K6 -> 0 | I3: ='Quick Setup'!L6 -> 0.005 | J3: ='Quick Setup'!M6 -> 0.01 | K3: ='Quick Setup'!N6 -> 0.015 | L3: ='Quick Setup'!O6 -> 0.02 | M3: ='Quick Setup'!P6 -> 0.03 | N3: ='Quick Setup'!D60 -> 0.75 | O3: =if(N3='Quick Setup'!$C$31,'Quick Setup'!$C32,if(N3='Quick Setup'!$D$31,'Quick Setup'!$D32,if(N3='Quick Setup'!$E$31,'Quick Setup'!$E32,if(N3='Quick Setup'!$F$31,'Quick Setup'!$F32,if(N3='Quick Setup'!$G$31,'Quick Setup'!$G32,if(N3='Quick Setup'!$H$31,'Quick Setup'!$H32,if(N3='Quick Setup'!$I$31,'Quick Setup'!$I32,if(N3='Quick Setup'!$J$31,'Quick Setup'!$J32,if(N3='Quick Setup'!$K$31,'Quick Setup'!$K32,if(N3='Quick Setup'!$L$31,'Quick Setup'!$L32,if(N3='Quick Setup'!$M$31,'Quick Setup'!$M32,if(N3='Quick Setup'!$N$31,'Quick Setup'!$N32,if(N3='Quick Setup'!$O$31,'Quick Setup'!$O32,if(N3='Quick Setup'!$P$31,'Quick Setup'!$P32,if(N3='Quick Setup'!$Q$31,'Quick Setup'!$Q32,if(N3='Quick Setup'!$R$31,'Quick Setup'!$R32,if(N3='Quick Setup'!$S$31,'Quick Setup'!$S32,if(N3='Quick Setup'!$T$31,'Quick Setup'!$T32,if(N3='Quick Setup'!$U$31,'Quick Setup'!$U32,if(N3='Quick Setup'!$V$31,'Quick Setup'!$V32,'Quick Setup'!$W32)))))))))))))))))))) -> 4 | P3: =if(N3='Quick Setup'!$C$45,'Quick Setup'!$C46,if(N3='Quick Setup'!$D$45,'Quick Setup'!$D46,if(N3='Quick Setup'!$E$45,'Quick Setup'!$E46,if(N3='Quick Setup'!$F$45,'Quick Setup'!$F46,if(N3='Quick Setup'!$G$45,'Quick Setup'!$G46,if(N3='Quick Setup'!$H$45,'Quick Setup'!$H46,if(N3='Quick Setup'!$I$45,'Quick Setup'!$I46,if(N3='Quick Setup'!$J$45,'Quick Setup'!$J46,if(N3='Quick Setup'!$K$45,'Quick Setup'!$K46,if(N3='Quick Setup'!$L$45,'Quick Setup'!$L46,if(N3='Quick Setup'!$M$45,'Quick Setup'!$M46,if(N3='Quick Setup'!$N$45,'Quick Setup'!$N46,if(N3='Quick Setup'!$O$45,'Quick Setup'!$O46,if(N3='Quick Setup'!$P$45,'Quick Setup'!$P46,if(N3='Quick Setup'!$Q$45,'Quick Setup'!$Q46,if(N3='Quick Setup'!$R$45,'Quick Setup'!$R46,if(N3='Quick Setup'!$S$45,'Quick Setup'!$S46,if(N3='Quick Setup'!$T$45,'Quick Setup'!$T46,if(N3='Quick Setup'!$U$45,'Quick Setup'!$U46,if(N3='Quick Setup'!$V$45,'Quick Setup'!$V46,'Quick Setup'!$W46)))))))))))))))))))) -> 8 | Q3: =E3 -> 5 | R3: =F3 -> -0.05 | S3: =G3 -> -0.02 | T3: =H3 -> 0 | U3: =I3 -> 0.005 | V3: =J3 -> 0.01 | W3: =K3 -> 0.015 | X3: =L3 -> 0.02 | Y3: =M3 -> 0.03 | Z3: ='Quick Setup'!E60 -> 0.8 | AA3: =if(Z3='Quick Setup'!$C$31,'Quick Setup'!$C32,if(Z3='Quick Setup'!$D$31,'Quick Setup'!$D32,if(Z3='Quick Setup'!$E$31,'Quick Setup'!$E32,if(Z3='Quick Setup'!$F$31,'Quick Setup'!$F32,if(Z3='Quick Setup'!$G$31,'Quick Setup'!$G32,if(Z3='Quick Setup'!$H$31,'Quick Setup'!$H32,if(Z3='Quick Setup'!$I$31,'Quick Setup'!$I32,if(Z3='Quick Setup'!$J$31,'Quick Setup'!$J32,if(Z3='Quick Setup'!$K$31,'Quick Setup'!$K32,if(Z3='Quick Setup'!$L$31,'Quick Setup'!$L32,if(Z3='Quick Setup'!$M$31,'Quick Setup'!$M32,if(Z3='Quick Setup'!$N$31,'Quick Setup'!$N32,if(Z3='Quick Setup'!$O$31,'Quick Setup'!$O32,if(Z3='Quick Setup'!$P$31,'Quick Setup'!$P32,if(Z3='Quick Setup'!$Q$31,'Quick Setup'!$Q32,if(Z3='Quick Setup'!$R$31,'Quick Setup'!$R32,if(Z3='Quick Setup'!$S$31,'Quick Setup'!$S32,if(Z3='Quick Setup'!$T$31,'Quick Setup'!$T32,if(Z3='Quick Setup'!$U$31,'Quick Setup'!$U32,if(Z3='Quick Setup'!$V$31,'Quick Setup'!$V32,'Quick Setup'!$W32)))))))))))))))))))) -> 3 | AB3: =if(Z3='Quick Setup'!$C$45,'Quick Setup'!$C46,if(Z3='Quick Setup'!$D$45,'Quick Setup'!$D46,if(Z3='Quick Setup'!$E$45,'Quick Setup'!$E46,if(Z3='Quick Setup'!$F$45,'Quick Setup'!$F46,if(Z3='Quick Setup'!$G$45,'Quick Setup'!$G46,if(Z3='Quick Setup'!$H$45,'Quick Setup'!$H46,if(Z3='Quick Setup'!$I$45,'Quick Setup'!$I46,if(Z3='Quick Setup'!$J$45,'Quick Setup'!$J46,if(Z3='Quick Setup'!$K$45,'Quick Setup'!$K46,if(Z3='Quick Setup'!$L$45,'Quick Setup'!$L46,if(Z3='Quick Setup'!$M$45,'Quick Setup'!$M46,if(Z3='Quick Setup'!$N$45,'Quick Setup'!$N46,if(Z3='Quick Setup'!$O$45,'Quick Setup'!$O46,if(Z3='Quick Setup'!$P$45,'Quick Setup'!$P46,if(Z3='Quick Setup'!$Q$45,'Quick Setup'!$Q46,if(Z3='Quick Setup'!$R$45,'Quick Setup'!$R46,if(Z3='Quick Setup'!$S$45,'Quick Setup'!$S46,if(Z3='Quick Setup'!$T$45,'Quick Setup'!$T46,if(Z3='Quick Setup'!$U$45,'Quick Setup'!$U46,if(Z3='Quick Setup'!$V$45,'Quick Setup'!$V46,'Quick Setup'!$W46)))))))))))))))))))) -> 6 | AC3: =Q3 -> 5 | AD3: =R3 -> -0.05 | AE3: =S3 -> -0.02 | AF3: =T3 -> 0 | AG3: =U3 -> 0.005 | AH3: =V3 -> 0.01 | AI3: =W3 -> 0.015 | AJ3: =X3 -> 0.02 | AK3: =Y3 -> 0.03 | AL3: ='Quick Setup'!F60 -> 0.725 | AM3: =if(AL3='Quick Setup'!$C$31,'Quick Setup'!$C32,if(AL3='Quick Setup'!$D$31,'Quick Setup'!$D32,if(AL3='Quick Setup'!$E$31,'Quick Setup'!$E32,if(AL3='Quick Setup'!$F$31,'Quick Setup'!$F32,if(AL3='Quick Setup'!$G$31,'Quick Setup'!$G32,if(AL3='Quick Setup'!$H$31,'Quick Setup'!$H32,if(AL3='Quick Setup'!$I$31,'Quick Setup'!$I32,if(AL3='Quick Setup'!$J$31,'Quick Setup'!$J32,if(AL3='Quick Setup'!$K$31,'Quick Setup'!$K32,if(AL3='Quick Setup'!$L$31,'Quick Setup'!$L32,if(AL3='Quick Setup'!$M$31,'Quick Setup'!$M32,if(AL3='Quick Setup'!$N$31,'Quick Setup'!$N32,if(AL3='Quick Setup'!$O$31,'Quick Setup'!$O32,if(AL3='Quick Setup'!$P$31,'Quick Setup'!$P32,if(AL3='Quick Setup'!$Q$31,'Quick Setup'!$Q32,if(AL3='Quick Setup'!$R$31,'Quick Setup'!$R32,if(AL3='Quick Setup'!$S$31,'Quick Setup'!$S32,if(AL3='Quick Setup'!$T$31,'Quick Setup'!$T32,if(AL3='Quick Setup'!$U$31,'Quick Setup'!$U32,if(AL3='Quick Setup'!$V$31,'Quick Setup'!$V32,'Quick Setup'!$W32)))))))))))))))))))) -> 5 | AN3: =if(AL3='Quick Setup'!$C$45,'Quick Setup'!$C46,if(AL3='Quick Setup'!$D$45,'Quick Setup'!$D46,if(AL3='Quick Setup'!$E$45,'Quick Setup'!$E46,if(AL3='Quick Setup'!$F$45,'Quick Setup'!$F46,if(AL3='Quick Setup'!$G$45,'Quick Setup'!$G46,if(AL3='Quick Setup'!$H$45,'Quick Setup'!$H46,if(AL3='Quick Setup'!$I$45,'Quick Setup'!$I46,if(AL3='Quick Setup'!$J$45,'Quick Setup'!$J46,if(AL3='Quick Setup'!$K$45,'Quick Setup'!$K46,if(AL3='Quick Setup'!$L$45,'Quick Setup'!$L46,if(AL3='Quick Setup'!$M$45,'Quick Setup'!$M46,if(AL3='Quick Setup'!$N$45,'Quick Setup'!$N46,if(AL3='Quick Setup'!$O$45,'Quick Setup'!$O46,if(AL3='Quick Setup'!$P$45,'Quick Setup'!$P46,if(AL3='Quick Setup'!$Q$45,'Quick Setup'!$Q46,if(AL3='Quick Setup'!$R$45,'Quick Setup'!$R46,if(AL3='Quick Setup'!$S$45,'Quick Setup'!$S46,if(AL3='Quick Setup'!$T$45,'Quick Setup'!$T46,if(AL3='Quick Setup'!$U$45,'Quick Setup'!$U46,if(AL3='Quick Setup'!$V$45,'Quick Setup'!$V46,'Quick Setup'!$W46)))))))))))))))))))) -> 9 | AO3: =AC3 -> 5 | AP3: =AD3 -> -0.05 | AQ3: =AE3 -> -0.02 | AR3: =AF3 -> 0 | AS3: =AG3 -> 0.005 | AT3: =AH3 -> 0.01 | AU3: =AI3 -> 0.015 | AV3: =AJ3 -> 0.02 | AW3: =AK3 -> 0.03 | AX3: ='Quick Setup'!G60 -> 0.775 | AY3: =if(AX3='Quick Setup'!$C$31,'Quick Setup'!$C32,if(AX3='Quick Setup'!$D$31,'Quick Setup'!$D32,if(AX3='Quick Setup'!$E$31,'Quick Setup'!$E32,if(AX3='Quick Setup'!$F$31,'Quick Setup'!$F32,if(AX3='Quick Setup'!$G$31,'Quick Setup'!$G32,if(AX3='Quick Setup'!$H$31,'Quick Setup'!$H32,if(AX3='Quick Setup'!$I$31,'Quick Setup'!$I32,if(AX3='Quick Setup'!$J$31,'Quick Setup'!$J32,if(AX3='Quick Setup'!$K$31,'Quick Setup'!$K32,if(AX3='Quick Setup'!$L$31,'Quick Setup'!$L32,if(AX3='Quick Setup'!$M$31,'Quick Setup'!$M32,if(AX3='Quick Setup'!$N$31,'Quick Setup'!$N32,if(AX3='Quick Setup'!$O$31,'Quick Setup'!$O32,if(AX3='Quick Setup'!$P$31,'Quick Setup'!$P32,if(AX3='Quick Setup'!$Q$31,'Quick Setup'!$Q32,if(AX3='Quick Setup'!$R$31,'Quick Setup'!$R32,if(AX3='Quick Setup'!$S$31,'Quick Setup'!$S32,if(AX3='Quick Setup'!$T$31,'Quick Setup'!$T32,if(AX3='Quick Setup'!$U$31,'Quick Setup'!$U32,if(AX3='Quick Setup'!$V$31,'Quick Setup'!$V32,'Quick Setup'!$W32)))))))))))))))))))) -> 4 | AZ3: =if(AX3='Quick Setup'!$C$45,'Quick Setup'!$C46,if(AX3='Quick Setup'!$D$45,'Quick Setup'!$D46,if(AX3='Quick Setup'!$E$45,'Quick Setup'!$E46,if(AX3='Quick Setup'!$F$45,'Quick Setup'!$F46,if(AX3='Quick Setup'!$G$45,'Quick Setup'!$G46,if(AX3='Quick Setup'!$H$45,'Quick Setup'!$H46,if(AX3='Quick Setup'!$I$45,'Quick Setup'!$I46,if(AX3='Quick Setup'!$J$45,'Quick Setup'!$J46,if(AX3='Quick Setup'!$K$45,'Quick Setup'!$K46,if(AX3='Quick Setup'!$L$45,'Quick Setup'!$L46,if(AX3='Quick Setup'!$M$45,'Quick Setup'!$M46,if(AX3='Quick Setup'!$N$45,'Quick Setup'!$N46,if(AX3='Quick Setup'!$O$45,'Quick Setup'!$O46,if(AX3='Quick Setup'!$P$45,'Quick Setup'!$P46,if(AX3='Quick Setup'!$Q$45,'Quick Setup'!$Q46,if(AX3='Quick Setup'!$R$45,'Quick Setup'!$R46,if(AX3='Quick Setup'!$S$45,'Quick Setup'!$S46,if(AX3='Quick Setup'!$T$45,'Quick Setup'!$T46,if(AX3='Quick Setup'!$U$45,'Quick Setup'!$U46,if(AX3='Quick Setup'!$V$45,'Quick Setup'!$V46,'Quick Setup'!$W46)))))))))))))))))))) -> 7 | BA3: =AO3 -> 5 | BB3: =AP3 -> -0.05 | BC3: =AQ3 -> -0.02 | BD3: =AR3 -> 0 | BE3: =AS3 -> 0.005 | BF3: =AT3 -> 0.01 | BG3: =AU3 -> 0.015 | BH3: =AV3 -> 0.02 | BI3: =AW3 -> 0.03 | BJ3: ='Quick Setup'!H60 -> 0.825 | BK3: =if(BJ3='Quick Setup'!$C$31,'Quick Setup'!$C32,if(BJ3='Quick Setup'!$D$31,'Quick Setup'!$D32,if(BJ3='Quick Setup'!$E$31,'Quick Setup'!$E32,if(BJ3='Quick Setup'!$F$31,'Quick Setup'!$F32,if(BJ3='Quick Setup'!$G$31,'Quick Setup'!$G32,if(BJ3='Quick Setup'!$H$31,'Quick Setup'!$H32,if(BJ3='Quick Setup'!$I$31,'Quick Setup'!$I32,if(BJ3='Quick Setup'!$J$31,'Quick Setup'!$J32,if(BJ3='Quick Setup'!$K$31,'Quick Setup'!$K32,if(BJ3='Quick Setup'!$L$31,'Quick Setup'!$L32,if(BJ3='Quick Setup'!$M$31,'Quick Setup'!$M32,if(BJ3='Quick Setup'!$N$31,'Quick Setup'!$N32,if(BJ3='Quick Setup'!$O$31,'Quick Setup'!$O32,if(BJ3='Quick Setup'!$P$31,'Quick Setup'!$P32,if(BJ3='Quick Setup'!$Q$31,'Quick Setup'!$Q32,if(BJ3='Quick Setup'!$R$31,'Quick Setup'!$R32,if(BJ3='Quick Setup'!$S$31,'Quick Setup'!$S32,if(BJ3='Quick Setup'!$T$31,'Quick Setup'!$T32,if(BJ3='Quick Setup'!$U$31,'Quick Setup'!$U32,if(BJ3='Quick Setup'!$V$31,'Quick Setup'!$V32,'Quick Setup'!$W32)))))))))))))))))))) -> 3 | BL3: =if(BJ3='Quick Setup'!$C$45,'Quick Setup'!$C46,if(BJ3='Quick Setup'!$D$45,'Quick Setup'!$D46,if(BJ3='Quick Setup'!$E$45,'Quick Setup'!$E46,if(BJ3='Quick Setup'!$F$45,'Quick Setup'!$F46,if(BJ3='Quick Setup'!$G$45,'Quick Setup'!$G46,if(BJ3='Quick Setup'!$H$45,'Quick Setup'!$H46,if(BJ3='Quick Setup'!$I$45,'Quick Setup'!$I46,if(BJ3='Quick Setup'!$J$45,'Quick Setup'!$J46,if(BJ3='Quick Setup'!$K$45,'Quick Setup'!$K46,if(BJ3='Quick Setup'!$L$45,'Quick Setup'!$L46,if(BJ3='Quick Setup'!$M$45,'Quick Setup'!$M46,if(BJ3='Quick Setup'!$N$45,'Quick Setup'!$N46,if(BJ3='Quick Setup'!$O$45,'Quick Setup'!$O46,if(BJ3='Quick Setup'!$P$45,'Quick Setup'!$P46,if(BJ3='Quick Setup'!$Q$45,'Quick Setup'!$Q46,if(BJ3='Quick Setup'!$R$45,'Quick Setup'!$R46,if(BJ3='Quick Setup'!$S$45,'Quick Setup'!$S46,if(BJ3='Quick Setup'!$T$45,'Quick Setup'!$T46,if(BJ3='Quick Setup'!$U$45,'Quick Setup'!$U46,if(BJ3='Quick Setup'!$V$45,'Quick Setup'!$V46,'Quick Setup'!$W46)))))))))))))))))))) -> 5 | BM3: =BA3 -> 5 | BN3: =BB3 -> -0.05 | BO3: =BC3 -> -0.02 | BP3: =BD3 -> 0 | BQ3: =BE3 -> 0.005 | BR3: =BF3 -> 0.01 | BS3: =BG3 -> 0.015 | BT3: =BH3 -> 0.02 | BU3: =BI3 -> 0.03 | BV3: ='Quick Setup'!I60 -> 0.6 | BW3: =if(BV3='Quick Setup'!$C$31,'Quick Setup'!$C32,if(BV3='Quick Setup'!$D$31,'Quick Setup'!$D32,if(BV3='Quick Setup'!$E$31,'Quick Setup'!$E32,if(BV3='Quick Setup'!$F$31,'Quick Setup'!$F32,if(BV3='Quick Setup'!$G$31,'Quick Setup'!$G32,if(BV3='Quick Setup'!$H$31,'Quick Setup'!$H32,if(BV3='Quick Setup'!$I$31,'Quick Setup'!$I32,if(BV3='Quick Setup'!$J$31,'Quick Setup'!$J32,if(BV3='Quick Setup'!$K$31,'Quick Setup'!$K32,if(BV3='Quick Setup'!$L$31,'Quick Setup'!$L32,if(BV3='Quick Setup'!$M$31,'Quick Setup'!$M32,if(BV3='Quick Setup'!$N$31,'Quick Setup'!$N32,if(BV3='Quick Setup'!$O$31,'Quick Setup'!$O32,if(BV3='Quick Setup'!$P$31,'Quick Setup'!$P32,if(BV3='Quick Setup'!$Q$31,'Quick Setup'!$Q32,if(BV3='Quick Setup'!$R$31,'Quick Setup'!$R32,if(BV3='Quick Setup'!$S$31,'Quick Setup'!$S32,if(BV3='Quick Setup'!$T$31,'Quick Setup'!$T32,if(BV3='Quick Setup'!$U$31,'Quick Setup'!$U32,if(BV3='Quick Setup'!$V$31,'Quick Setup'!$V32,'Quick Setup'!$W32)))))))))))))))))))) -> 7 | BX3: =if(BV3='Quick Setup'!$C$45,'Quick Setup'!$C46,if(BV3='Quick Setup'!$D$45,'Quick Setup'!$D46,if(BV3='Quick Setup'!$E$45,'Quick Setup'!$E46,if(BV3='Quick Setup'!$F$45,'Quick Setup'!$F46,if(BV3='Quick Setup'!$G$45,'Quick Setup'!$G46,if(BV3='Quick Setup'!$H$45,'Quick Setup'!$H46,if(BV3='Quick Setup'!$I$45,'Quick Setup'!$I46,if(BV3='Quick Setup'!$J$45,'Quick Setup'!$J46,if(BV3='Quick Setup'!$K$45,'Quick Setup'!$K46,if(BV3='Quick Setup'!$L$45,'Quick Setup'!$L46,if(BV3='Quick Setup'!$M$45,'Quick Setup'!$M46,if(BV3='Quick Setup'!$N$45,'Quick Setup'!$N46,if(BV3='Quick Setup'!$O$45,'Quick Setup'!$O46,if(BV3='Quick Setup'!$P$45,'Quick Setup'!$P46,if(BV3='Quick Setup'!$Q$45,'Quick Setup'!$Q46,if(BV3='Quick Setup'!$R$45,'Quick Setup'!$R46,if(BV3='Quick Setup'!$S$45,'Quick Setup'!$S46,if(BV3='Quick Setup'!$T$45,'Quick Setup'!$T46,if(BV3='Quick Setup'!$U$45,'Quick Setup'!$U46,if(BV3='Quick Setup'!$V$45,'Quick Setup'!$V46,'Quick Setup'!$W46)))))))))))))))))))) -> 14 | BY3: =BM3 -> 5 | BZ3: =BN3 -> -0.05 | CA3: =BO3 -> -0.02 | CB3: =BP3 -> 0 | CC3: =BQ3 -> 0.005 | CD3: =BR3 -> 0.01 | CE3: =BS3 -> 0.015 | CF3: =BT3 -> 0.02 | CG3: =BU3 -> 0.03 | CH3: ='Quick Setup'!J60 -> 0.75 | CI3: =if(CH3='Quick Setup'!$C$31,'Quick Setup'!$C32,if(CH3='Quick Setup'!$D$31,'Quick Setup'!$D32,if(CH3='Quick Setup'!$E$31,'Quick Setup'!$E32,if(CH3='Quick Setup'!$F$31,'Quick Setup'!$F32,if(CH3='Quick Setup'!$G$31,'Quick Setup'!$G32,if(CH3='Quick Setup'!$H$31,'Quick Setup'!$H32,if(CH3='Quick Setup'!$I$31,'Quick Setup'!$I32,if(CH3='Quick Setup'!$J$31,'Quick Setup'!$J32,if(CH3='Quick Setup'!$K$31,'Quick Setup'!$K32,if(CH3='Quick Setup'!$L$31,'Quick Setup'!$L32,if(CH3='Quick Setup'!$M$31,'Quick Setup'!$M32,if(CH3='Quick Setup'!$N$31,'Quick Setup'!$N32,if(CH3='Quick Setup'!$O$31,'Quick Setup'!$O32,if(CH3='Quick Setup'!$P$31,'Quick Setup'!$P32,if(CH3='Quick Setup'!$Q$31,'Quick Setup'!$Q32,if(CH3='Quick Setup'!$R$31,'Quick Setup'!$R32,if(CH3='Quick Setup'!$S$31,'Quick Setup'!$S32,if(CH3='Quick Setup'!$T$31,'Quick Setup'!$T32,if(CH3='Quick Setup'!$U$31,'Quick Setup'!$U32,if(CH3='Quick Setup'!$V$31,'Quick Setup'!$V32,'Quick Setup'!$W32)))))))))))))))))))) -> 4 | CJ3: =if(CH3='Quick Setup'!$C$45,'Quick Setup'!$C46,if(CH3='Quick Setup'!$D$45,'Quick Setup'!$D46,if(CH3='Quick Setup'!$E$45,'Quick Setup'!$E46,if(CH3='Quick Setup'!$F$45,'Quick Setup'!$F46,if(CH3='Quick Setup'!$G$45,'Quick Setup'!$G46,if(CH3='Quick Setup'!$H$45,'Quick Setup'!$H46,if(CH3='Quick Setup'!$I$45,'Quick Setup'!$I46,if(CH3='Quick Setup'!$J$45,'Quick Setup'!$J46,if(CH3='Quick Setup'!$K$45,'Quick Setup'!$K46,if(CH3='Quick Setup'!$L$45,'Quick Setup'!$L46,if(CH3='Quick Setup'!$M$45,'Quick Setup'!$M46,if(CH3='Quick Setup'!$N$45,'Quick Setup'!$N46,if(CH3='Quick Setup'!$O$45,'Quick Setup'!$O46,if(CH3='Quick Setup'!$P$45,'Quick Setup'!$P46,if(CH3='Quick Setup'!$Q$45,'Quick Setup'!$Q46,if(CH3='Quick Setup'!$R$45,'Quick Setup'!$R46,if(CH3='Quick Setup'!$S$45,'Quick Setup'!$S46,if(CH3='Quick Setup'!$T$45,'Quick Setup'!$T46,if(CH3='Quick Setup'!$U$45,'Quick Setup'!$U46,if(CH3='Quick Setup'!$V$45,'Quick Setup'!$V46,'Quick Setup'!$W46)))))))))))))))))))) -> 8 | CK3: =BY3 -> 5 | CL3: =BZ3 -> -0.05 | CM3: =CA3 -> -0.02 | CN3: =CB3 -> 0 | CO3: =CC3 -> 0.005 | CP3: =CD3 -> 0.01 | CQ3: =CE3 -> 0.015 | CR3: =CF3 -> 0.02 | CS3: =CG3 -> 0.03 | CT3: ='Quick Setup'!K60 -> 0.8 | CU3: =if(CT3='Quick Setup'!$C$31,'Quick Setup'!$C32,if(CT3='Quick Setup'!$D$31,'Quick Setup'!$D32,if(CT3='Quick Setup'!$E$31,'Quick Setup'!$E32,if(CT3='Quick Setup'!$F$31,'Quick Setup'!$F32,if(CT3='Quick Setup'!$G$31,'Quick Setup'!$G32,if(CT3='Quick Setup'!$H$31,'Quick Setup'!$H32,if(CT3='Quick Setup'!$I$31,'Quick Setup'!$I32,if(CT3='Quick Setup'!$J$31,'Quick Setup'!$J32,if(CT3='Quick Setup'!$K$31,'Quick Setup'!$K32,if(CT3='Quick Setup'!$L$31,'Quick Setup'!$L32,if(CT3='Quick Setup'!$M$31,'Quick Setup'!$M32,if(CT3='Quick Setup'!$N$31,'Quick Setup'!$N32,if(CT3='Quick Setup'!$O$31,'Quick Setup'!$O32,if(CT3='Quick Setup'!$P$31,'Quick Setup'!$P32,if(CT3='Quick Setup'!$Q$31,'Quick Setup'!$Q32,if(CT3='Quick Setup'!$R$31,'Quick Setup'!$R32,if(CT3='Quick Setup'!$S$31,'Quick Setup'!$S32,if(CT3='Quick Setup'!$T$31,'Quick Setup'!$T32,if(CT3='Quick Setup'!$U$31,'Quick Setup'!$U32,if(CT3='Quick Setup'!$V$31,'Quick Setup'!$V32,'Quick Setup'!$W32)))))))))))))))))))) -> 3 | CV3: =if(CT3='Quick Setup'!$C$45,'Quick Setup'!$C46,if(CT3='Quick Setup'!$D$45,'Quick Setup'!$D46,if(CT3='Quick Setup'!$E$45,'Quick Setup'!$E46,if(CT3='Quick Setup'!$F$45,'Quick Setup'!$F46,if(CT3='Quick Setup'!$G$45,'Quick Setup'!$G46,if(CT3='Quick Setup'!$H$45,'Quick Setup'!$H46,if(CT3='Quick Setup'!$I$45,'Quick Setup'!$I46,if(CT3='Quick Setup'!$J$45,'Quick Setup'!$J46,if(CT3='Quick Setup'!$K$45,'Quick Setup'!$K46,if(CT3='Quick Setup'!$L$45,'Quick Setup'!$L46,if(CT3='Quick Setup'!$M$45,'Quick Setup'!$M46,if(CT3='Quick Setup'!$N$45,'Quick Setup'!$N46,if(CT3='Quick Setup'!$O$45,'Quick Setup'!$O46,if(CT3='Quick Setup'!$P$45,'Quick Setup'!$P46,if(CT3='Quick Setup'!$Q$45,'Quick Setup'!$Q46,if(CT3='Quick Setup'!$R$45,'Quick Setup'!$R46,if(CT3='Quick Setup'!$S$45,'Quick Setup'!$S46,if(CT3='Quick Setup'!$T$45,'Quick Setup'!$T46,if(CT3='Quick Setup'!$U$45,'Quick Setup'!$U46,if(CT3='Quick Setup'!$V$45,'Quick Setup'!$V46,'Quick Setup'!$W46)))))))))))))))))))) -> 6 | CW3: =CK3 -> 5 | CX3: =CL3 -> -0.05 | CY3: =CM3 -> -0.02 | CZ3: =CN3 -> 0 | DA3: =CO3 -> 0.005 | DB3: =CP3 -> 0.01 | DC3: =CQ3 -> 0.015 | DD3: =CR3 -> 0.02 | DE3: =CS3 -> 0.03 | DF3: ='Quick Setup'!L60 -> 0.85 | DG3: =if(DF3='Quick Setup'!$C$31,'Quick Setup'!$C32,if(DF3='Quick Setup'!$D$31,'Quick Setup'!$D32,if(DF3='Quick Setup'!$E$31,'Quick Setup'!$E32,if(DF3='Quick Setup'!$F$31,'Quick Setup'!$F32,if(DF3='Quick Setup'!$G$31,'Quick Setup'!$G32,if(DF3='Quick Setup'!$H$31,'Quick Setup'!$H32,if(DF3='Quick Setup'!$I$31,'Quick Setup'!$I32,if(DF3='Quick Setup'!$J$31,'Quick Setup'!$J32,if(DF3='Quick Setup'!$K$31,'Quick Setup'!$K32,if(DF3='Quick Setup'!$L$31,'Quick Setup'!$L32,if(DF3='Quick Setup'!$M$31,'Quick Setup'!$M32,if(DF3='Quick Setup'!$N$31,'Quick Setup'!$N32,if(DF3='Quick Setup'!$O$31,'Quick Setup'!$O32,if(DF3='Quick Setup'!$P$31,'Quick Setup'!$P32,if(DF3='Quick Setup'!$Q$31,'Quick Setup'!$Q32,if(DF3='Quick Setup'!$R$31,'Quick Setup'!$R32,if(DF3='Quick Setup'!$S$31,'Quick Setup'!$S32,if(DF3='Quick Setup'!$T$31,'Quick Setup'!$T32,if(DF3='Quick Setup'!$U$31,'Quick Setup'!$U32,if(DF3='Quick Setup'!$V$31,'Quick Setup'!$V32,'Quick Setup'!$W32)))))))))))))))))))) -> 2 | DH3: =if(DF3='Quick Setup'!$C$45,'Quick Setup'!$C46,if(DF3='Quick Setup'!$D$45,'Quick Setup'!$D46,if(DF3='Quick Setup'!$E$45,'Quick Setup'!$E46,if(DF3='Quick Setup'!$F$45,'Quick Setup'!$F46,if(DF3='Quick Setup'!$G$45,'Quick Setup'!$G46,if(DF3='Quick Setup'!$H$45,'Quick Setup'!$H46,if(DF3='Quick Setup'!$I$45,'Quick Setup'!$I46,if(DF3='Quick Setup'!$J$45,'Quick Setup'!$J46,if(DF3='Quick Setup'!$K$45,'Quick Setup'!$K46,if(DF3='Quick Setup'!$L$45,'Quick Setup'!$L46,if(DF3='Quick Setup'!$M$45,'Quick Setup'!$M46,if(DF3='Quick Setup'!$N$45,'Quick Setup'!$N46,if(DF3='Quick Setup'!$O$45,'Quick Setup'!$O46,if(DF3='Quick Setup'!$P$45,'Quick Setup'!$P46,if(DF3='Quick Setup'!$Q$45,'Quick Setup'!$Q46,if(DF3='Quick Setup'!$R$45,'Quick Setup'!$R46,if(DF3='Quick Setup'!$S$45,'Quick Setup'!$S46,if(DF3='Quick Setup'!$T$45,'Quick Setup'!$T46,if(DF3='Quick Setup'!$U$45,'Quick Setup'!$U46,if(DF3='Quick Setup'!$V$45,'Quick Setup'!$V46,'Quick Setup'!$W46)))))))))))))))))))) -> 4 | DI3: =CW3 -> 5 | DJ3: =CX3 -> -0.05 | DK3: =CY3 -> -0.02 | DL3: =CZ3 -> 0 | DM3: =DA3 -> 0.005 | DN3: =DB3 -> 0.01 | DO3: =DC3 -> 0.015 | DP3: =DD3 -> 0.02 | DQ3: =DE3 -> 0.03 | DR3: ='Quick Setup'!M60 -> 0.775 | DS3: =if(DR3='Quick Setup'!$C$31,'Quick Setup'!$C32,if(DR3='Quick Setup'!$D$31,'Quick Setup'!$D32,if(DR3='Quick Setup'!$E$31,'Quick Setup'!$E32,if(DR3='Quick Setup'!$F$31,'Quick Setup'!$F32,if(DR3='Quick Setup'!$G$31,'Quick Setup'!$G32,if(DR3='Quick Setup'!$H$31,'Quick Setup'!$H32,if(DR3='Quick Setup'!$I$31,'Quick Setup'!$I32,if(DR3='Quick Setup'!$J$31,'Quick Setup'!$J32,if(DR3='Quick Setup'!$K$31,'Quick Setup'!$K32,if(DR3='Quick Setup'!$L$31,'Quick Setup'!$L32,if(DR3='Quick Setup'!$M$31,'Quick Setup'!$M32,if(DR3='Quick Setup'!$N$31,'Quick Setup'!$N32,if(DR3='Quick Setup'!$O$31,'Quick Setup'!$O32,if(DR3='Quick Setup'!$P$31,'Quick Setup'!$P32,if(DR3='Quick Setup'!$Q$31,'Quick Setup'!$Q32,if(DR3='Quick Setup'!$R$31,'Quick Setup'!$R32,if(DR3='Quick Setup'!$S$31,'Quick Setup'!$S32,if(DR3='Quick Setup'!$T$31,'Quick Setup'!$T32,if(DR3='Quick Setup'!$U$31,'Quick Setup'!$U32,if(DR3='Quick Setup'!$V$31,'Quick Setup'!$V32,'Quick Setup'!$W32)))))))))))))))))))) -> 4 | DT3: =if(DR3='Quick Setup'!$C$45,'Quick Setup'!$C46,if(DR3='Quick Setup'!$D$45,'Quick Setup'!$D46,if(DR3='Quick Setup'!$E$45,'Quick Setup'!$E46,if(DR3='Quick Setup'!$F$45,'Quick Setup'!$F46,if(DR3='Quick Setup'!$G$45,'Quick Setup'!$G46,if(DR3='Quick Setup'!$H$45,'Quick Setup'!$H46,if(DR3='Quick Setup'!$I$45,'Quick Setup'!$I46,if(DR3='Quick Setup'!$J$45,'Quick Setup'!$J46,if(DR3='Quick Setup'!$K$45,'Quick Setup'!$K46,if(DR3='Quick Setup'!$L$45,'Quick Setup'!$L46,if(DR3='Quick Setup'!$M$45,'Quick Setup'!$M46,if(DR3='Quick Setup'!$N$45,'Quick Setup'!$N46,if(DR3='Quick Setup'!$O$45,'Quick Setup'!$O46,if(DR3='Quick Setup'!$P$45,'Quick Setup'!$P46,if(DR3='Quick Setup'!$Q$45,'Quick Setup'!$Q46,if(DR3='Quick Setup'!$R$45,'Quick Setup'!$R46,if(DR3='Quick Setup'!$S$45,'Quick Setup'!$S46,if(DR3='Quick Setup'!$T$45,'Quick Setup'!$T46,if(DR3='Quick Setup'!$U$45,'Quick Setup'!$U46,if(DR3='Quick Setup'!$V$45,'Quick Setup'!$V46,'Quick Setup'!$W46)))))))))))))))))))) -> 7 | DU3: =DI3 -> 5 | DV3: =DJ3 -> -0.05 | DW3: =DK3 -> -0.02 | DX3: =DL3 -> 0 | DY3: =DM3 -> 0.005 | DZ3: =DN3 -> 0.01 | EA3: =DO3 -> 0.015 | EB3: =DP3 -> 0.02 | EC3: =DQ3 -> 0.03 | ED3: ='Quick Setup'!N60 -> 0.825 | EE3: =if(ED3='Quick Setup'!$C$31,'Quick Setup'!$C32,if(ED3='Quick Setup'!$D$31,'Quick Setup'!$D32,if(ED3='Quick Setup'!$E$31,'Quick Setup'!$E32,if(ED3='Quick Setup'!$F$31,'Quick Setup'!$F32,if(ED3='Quick Setup'!$G$31,'Quick Setup'!$G32,if(ED3='Quick Setup'!$H$31,'Quick Setup'!$H32,if(ED3='Quick Setup'!$I$31,'Quick Setup'!$I32,if(ED3='Quick Setup'!$J$31,'Quick Setup'!$J32,if(ED3='Quick Setup'!$K$31,'Quick Setup'!$K32,if(ED3='Quick Setup'!$L$31,'Quick Setup'!$L32,if(ED3='Quick Setup'!$M$31,'Quick Setup'!$M32,if(ED3='Quick Setup'!$N$31,'Quick Setup'!$N32,if(ED3='Quick Setup'!$O$31,'Quick Setup'!$O32,if(ED3='Quick Setup'!$P$31,'Quick Setup'!$P32,if(ED3='Quick Setup'!$Q$31,'Quick Setup'!$Q32,if(ED3='Quick Setup'!$R$31,'Quick Setup'!$R32,if(ED3='Quick Setup'!$S$31,'Quick Setup'!$S32,if(ED3='Quick Setup'!$T$31,'Quick Setup'!$T32,if(ED3='Quick Setup'!$U$31,'Quick Setup'!$U32,if(ED3='Quick Setup'!$V$31,'Quick Setup'!$V32,'Quick Setup'!$W32)))))))))))))))))))) -> 3 | EF3: =if(ED3='Quick Setup'!$C$45,'Quick Setup'!$C46,if(ED3='Quick Setup'!$D$45,'Quick Setup'!$D46,if(ED3='Quick Setup'!$E$45,'Quick Setup'!$E46,if(ED3='Quick Setup'!$F$45,'Quick Setup'!$F46,if(ED3='Quick Setup'!$G$45,'Quick Setup'!$G46,if(ED3='Quick Setup'!$H$45,'Quick Setup'!$H46,if(ED3='Quick Setup'!$I$45,'Quick Setup'!$I46,if(ED3='Quick Setup'!$J$45,'Quick Setup'!$J46,if(ED3='Quick Setup'!$K$45,'Quick Setup'!$K46,if(ED3='Quick Setup'!$L$45,'Quick Setup'!$L46,if(ED3='Quick Setup'!$M$45,'Quick Setup'!$M46,if(ED3='Quick Setup'!$N$45,'Quick Setup'!$N46,if(ED3='Quick Setup'!$O$45,'Quick Setup'!$O46,if(ED3='Quick Setup'!$P$45,'Quick Setup'!$P46,if(ED3='Quick Setup'!$Q$45,'Quick Setup'!$Q46,if(ED3='Quick Setup'!$R$45,'Quick Setup'!$R46,if(ED3='Quick Setup'!$S$45,'Quick Setup'!$S46,if(ED3='Quick Setup'!$T$45,'Quick Setup'!$T46,if(ED3='Quick Setup'!$U$45,'Quick Setup'!$U46,if(ED3='Quick Setup'!$V$45,'Quick Setup'!$V46,'Quick Setup'!$W46)))))))))))))))))))) -> 5 | EG3: =DU3 -> 5 | EH3: =DV3 -> -0.05 | EI3: =DW3 -> -0.02 | EJ3: =DX3 -> 0 | EK3: =DY3 -> 0.005 | EL3: =DZ3 -> 0.01 | EM3: =EA3 -> 0.015 | EN3: =EB3 -> 0.02 | EO3: =EC3 -> 0.03 | EP3: ='Quick Setup'!O60 -> 0.875 | EQ3: =if(EP3='Quick Setup'!$C$31,'Quick Setup'!$C32,if(EP3='Quick Setup'!$D$31,'Quick Setup'!$D32,if(EP3='Quick Setup'!$E$31,'Quick Setup'!$E32,if(EP3='Quick Setup'!$F$31,'Quick Setup'!$F32,if(EP3='Quick Setup'!$G$31,'Quick Setup'!$G32,if(EP3='Quick Setup'!$H$31,'Quick Setup'!$H32,if(EP3='Quick Setup'!$I$31,'Quick Setup'!$I32,if(EP3='Quick Setup'!$J$31,'Quick Setup'!$J32,if(EP3='Quick Setup'!$K$31,'Quick Setup'!$K32,if(EP3='Quick Setup'!$L$31,'Quick Setup'!$L32,if(EP3='Quick Setup'!$M$31,'Quick Setup'!$M32,if(EP3='Quick Setup'!$N$31,'Quick Setup'!$N32,if(EP3='Quick Setup'!$O$31,'Quick Setup'!$O32,if(EP3='Quick Setup'!$P$31,'Quick Setup'!$P32,if(EP3='Quick Setup'!$Q$31,'Quick Setup'!$Q32,if(EP3='Quick Setup'!$R$31,'Quick Setup'!$R32,if(EP3='Quick Setup'!$S$31,'Quick Setup'!$S32,if(EP3='Quick Setup'!$T$31,'Quick Setup'!$T32,if(EP3='Quick Setup'!$U$31,'Quick Setup'!$U32,if(EP3='Quick Setup'!$V$31,'Quick Setup'!$V32,'Quick Setup'!$W32)))))))))))))))))))) -> 2 | ER3: =if(EP3='Quick Setup'!$C$45,'Quick Setup'!$C46,if(EP3='Quick Setup'!$D$45,'Quick Setup'!$D46,if(EP3='Quick Setup'!$E$45,'Quick Setup'!$E46,if(EP3='Quick Setup'!$F$45,'Quick Setup'!$F46,if(EP3='Quick Setup'!$G$45,'Quick Setup'!$G46,if(EP3='Quick Setup'!$H$45,'Quick Setup'!$H46,if(EP3='Quick Setup'!$I$45,'Quick Setup'!$I46,if(EP3='Quick Setup'!$J$45,'Quick Setup'!$J46,if(EP3='Quick Setup'!$K$45,'Quick Setup'!$K46,if(EP3='Quick Setup'!$L$45,'Quick Setup'!$L46,if(EP3='Quick Setup'!$M$45,'Quick Setup'!$M46,if(EP3='Quick Setup'!$N$45,'Quick Setup'!$N46,if(EP3='Quick Setup'!$O$45,'Quick Setup'!$O46,if(EP3='Quick Setup'!$P$45,'Quick Setup'!$P46,if(EP3='Quick Setup'!$Q$45,'Quick Setup'!$Q46,if(EP3='Quick Setup'!$R$45,'Quick Setup'!$R46,if(EP3='Quick Setup'!$S$45,'Quick Setup'!$S46,if(EP3='Quick Setup'!$T$45,'Quick Setup'!$T46,if(EP3='Quick Setup'!$U$45,'Quick Setup'!$U46,if(EP3='Quick Setup'!$V$45,'Quick Setup'!$V46,'Quick Setup'!$W46)))))))))))))))))))) -> 3 | ES3: =EG3 -> 5 | ET3: =EH3 -> -0.05 | EU3: =EI3 -> -0.02 | EV3: =EJ3 -> 0 | EW3: =EK3 -> 0.005 | EX3: =EL3 -> 0.01 | EY3: =EM3 -> 0.015 | EZ3: =EN3 -> 0.02 | FA3: =EO3 -> 0.03 | FB3: ='Quick Setup'!P60 -> 0.6 | FC3: =if(FB3='Quick Setup'!$C$31,'Quick Setup'!$C32,if(FB3='Quick Setup'!$D$31,'Quick Setup'!$D32,if(FB3='Quick Setup'!$E$31,'Quick Setup'!$E32,if(FB3='Quick Setup'!$F$31,'Quick Setup'!$F32,if(FB3='Quick Setup'!$G$31,'Quick Setup'!$G32,if(FB3='Quick Setup'!$H$31,'Quick Setup'!$H32,if(FB3='Quick Setup'!$I$31,'Quick Setup'!$I32,if(FB3='Quick Setup'!$J$31,'Quick Setup'!$J32,if(FB3='Quick Setup'!$K$31,'Quick Setup'!$K32,if(FB3='Quick Setup'!$L$31,'Quick Setup'!$L32,if(FB3='Quick Setup'!$M$31,'Quick Setup'!$M32,if(FB3='Quick Setup'!$N$31,'Quick Setup'!$N32,if(FB3='Quick Setup'!$O$31,'Quick Setup'!$O32,if(FB3='Quick Setup'!$P$31,'Quick Setup'!$P32,if(FB3='Quick Setup'!$Q$31,'Quick Setup'!$Q32,if(FB3='Quick Setup'!$R$31,'Quick Setup'!$R32,if(FB3='Quick Setup'!$S$31,'Quick Setup'!$S32,if(FB3='Quick Setup'!$T$31,'Quick Setup'!$T32,if(FB3='Quick Setup'!$U$31,'Quick Setup'!$U32,if(FB3='Quick Setup'!$V$31,'Quick Setup'!$V32,'Quick Setup'!$W32)))))))))))))))))))) -> 7 | FD3: =if(FB3='Quick Setup'!$C$45,'Quick Setup'!$C46,if(FB3='Quick Setup'!$D$45,'Quick Setup'!$D46,if(FB3='Quick Setup'!$E$45,'Quick Setup'!$E46,if(FB3='Quick Setup'!$F$45,'Quick Setup'!$F46,if(FB3='Quick Setup'!$G$45,'Quick Setup'!$G46,if(FB3='Quick Setup'!$H$45,'Quick Setup'!$H46,if(FB3='Quick Setup'!$I$45,'Quick Setup'!$I46,if(FB3='Quick Setup'!$J$45,'Quick Setup'!$J46,if(FB3='Quick Setup'!$K$45,'Quick Setup'!$K46,if(FB3='Quick Setup'!$L$45,'Quick Setup'!$L46,if(FB3='Quick Setup'!$M$45,'Quick Setup'!$M46,if(FB3='Quick Setup'!$N$45,'Quick Setup'!$N46,if(FB3='Quick Setup'!$O$45,'Quick Setup'!$O46,if(FB3='Quick Setup'!$P$45,'Quick Setup'!$P46,if(FB3='Quick Setup'!$Q$45,'Quick Setup'!$Q46,if(FB3='Quick Setup'!$R$45,'Quick Setup'!$R46,if(FB3='Quick Setup'!$S$45,'Quick Setup'!$S46,if(FB3='Quick Setup'!$T$45,'Quick Setup'!$T46,if(FB3='Quick Setup'!$U$45,'Quick Setup'!$U46,if(FB3='Quick Setup'!$V$45,'Quick Setup'!$V46,'Quick Setup'!$W46)))))))))))))))))))) -> 14 | FE3: =ES3 -> 5 | FF3: =ET3 -> -0.05 | FG3: =EU3 -> -0.02 | FH3: =EV3 -> 0 | FI3: =EW3 -> 0.005 | FJ3: =EX3 -> 0.01 | FK3: =EY3 -> 0.015 | FL3: =EZ3 -> 0.02 | FM3: =FA3 -> 0.03 | FN3: ='Quick Setup'!Q60 -> 0.8 | FO3: =if(FN3='Quick Setup'!$C$31,'Quick Setup'!$C32,if(FN3='Quick Setup'!$D$31,'Quick Setup'!$D32,if(FN3='Quick Setup'!$E$31,'Quick Setup'!$E32,if(FN3='Quick Setup'!$F$31,'Quick Setup'!$F32,if(FN3='Quick Setup'!$G$31,'Quick Setup'!$G32,if(FN3='Quick Setup'!$H$31,'Quick Setup'!$H32,if(FN3='Quick Setup'!$I$31,'Quick Setup'!$I32,if(FN3='Quick Setup'!$J$31,'Quick Setup'!$J32,if(FN3='Quick Setup'!$K$31,'Quick Setup'!$K32,if(FN3='Quick Setup'!$L$31,'Quick Setup'!$L32,if(FN3='Quick Setup'!$M$31,'Quick Setup'!$M32,if(FN3='Quick Setup'!$N$31,'Quick Setup'!$N32,if(FN3='Quick Setup'!$O$31,'Quick Setup'!$O32,if(FN3='Quick Setup'!$P$31,'Quick Setup'!$P32,if(FN3='Quick Setup'!$Q$31,'Quick Setup'!$Q32,if(FN3='Quick Setup'!$R$31,'Quick Setup'!$R32,if(FN3='Quick Setup'!$S$31,'Quick Setup'!$S32,if(FN3='Quick Setup'!$T$31,'Quick Setup'!$T32,if(FN3='Quick Setup'!$U$31,'Quick Setup'!$U32,if(FN3='Quick Setup'!$V$31,'Quick Setup'!$V32,'Quick Setup'!$W32)))))))))))))))))))) -> 3 | FP3: =if(FN3='Quick Setup'!$C$45,'Quick Setup'!$C46,if(FN3='Quick Setup'!$D$45,'Quick Setup'!$D46,if(FN3='Quick Setup'!$E$45,'Quick Setup'!$E46,if(FN3='Quick Setup'!$F$45,'Quick Setup'!$F46,if(FN3='Quick Setup'!$G$45,'Quick Setup'!$G46,if(FN3='Quick Setup'!$H$45,'Quick Setup'!$H46,if(FN3='Quick Setup'!$I$45,'Quick Setup'!$I46,if(FN3='Quick Setup'!$J$45,'Quick Setup'!$J46,if(FN3='Quick Setup'!$K$45,'Quick Setup'!$K46,if(FN3='Quick Setup'!$L$45,'Quick Setup'!$L46,if(FN3='Quick Setup'!$M$45,'Quick Setup'!$M46,if(FN3='Quick Setup'!$N$45,'Quick Setup'!$N46,if(FN3='Quick Setup'!$O$45,'Quick Setup'!$O46,if(FN3='Quick Setup'!$P$45,'Quick Setup'!$P46,if(FN3='Quick Setup'!$Q$45,'Quick Setup'!$Q46,if(FN3='Quick Setup'!$R$45,'Quick Setup'!$R46,if(FN3='Quick Setup'!$S$45,'Quick Setup'!$S46,if(FN3='Quick Setup'!$T$45,'Quick Setup'!$T46,if(FN3='Quick Setup'!$U$45,'Quick Setup'!$U46,if(FN3='Quick Setup'!$V$45,'Quick Setup'!$V46,'Quick Setup'!$W46)))))))))))))))))))) -> 6 | FQ3: =FE3 -> 5 | FR3: =FF3 -> -0.05 | FS3: =FG3 -> -0.02 | FT3: =FH3 -> 0 | FU3: =FI3 -> 0.005 | FV3: =FJ3 -> 0.01 | FW3: =FK3 -> 0.015 | FX3: =FL3 -> 0.02 | FY3: =FM3 -> 0.03 | FZ3: ='Quick Setup'!R60 -> 0.85 | GA3: =if(FZ3='Quick Setup'!$C$31,'Quick Setup'!$C32,if(FZ3='Quick Setup'!$D$31,'Quick Setup'!$D32,if(FZ3='Quick Setup'!$E$31,'Quick Setup'!$E32,if(FZ3='Quick Setup'!$F$31,'Quick Setup'!$F32,if(FZ3='Quick Setup'!$G$31,'Quick Setup'!$G32,if(FZ3='Quick Setup'!$H$31,'Quick Setup'!$H32,if(FZ3='Quick Setup'!$I$31,'Quick Setup'!$I32,if(FZ3='Quick Setup'!$J$31,'Quick Setup'!$J32,if(FZ3='Quick Setup'!$K$31,'Quick Setup'!$K32,if(FZ3='Quick Setup'!$L$31,'Quick Setup'!$L32,if(FZ3='Quick Setup'!$M$31,'Quick Setup'!$M32,if(FZ3='Quick Setup'!$N$31,'Quick Setup'!$N32,if(FZ3='Quick Setup'!$O$31,'Quick Setup'!$O32,if(FZ3='Quick Setup'!$P$31,'Quick Setup'!$P32,if(FZ3='Quick Setup'!$Q$31,'Quick Setup'!$Q32,if(FZ3='Quick Setup'!$R$31,'Quick Setup'!$R32,if(FZ3='Quick Setup'!$S$31,'Quick Setup'!$S32,if(FZ3='Quick Setup'!$T$31,'Quick Setup'!$T32,if(FZ3='Quick Setup'!$U$31,'Quick Setup'!$U32,if(FZ3='Quick Setup'!$V$31,'Quick Setup'!$V32,'Quick Setup'!$W32)))))))))))))))))))) -> 2 | GB3: =if(FZ3='Quick Setup'!$C$45,'Quick Setup'!$C46,if(FZ3='Quick Setup'!$D$45,'Quick Setup'!$D46,if(FZ3='Quick Setup'!$E$45,'Quick Setup'!$E46,if(FZ3='Quick Setup'!$F$45,'Quick Setup'!$F46,if(FZ3='Quick Setup'!$G$45,'Quick Setup'!$G46,if(FZ3='Quick Setup'!$H$45,'Quick Setup'!$H46,if(FZ3='Quick Setup'!$I$45,'Quick Setup'!$I46,if(FZ3='Quick Setup'!$J$45,'Quick Setup'!$J46,if(FZ3='Quick Setup'!$K$45,'Quick Setup'!$K46,if(FZ3='Quick Setup'!$L$45,'Quick Setup'!$L46,if(FZ3='Quick Setup'!$M$45,'Quick Setup'!$M46,if(FZ3='Quick Setup'!$N$45,'Quick Setup'!$N46,if(FZ3='Quick Setup'!$O$45,'Quick Setup'!$O46,if(FZ3='Quick Setup'!$P$45,'Quick Setup'!$P46,if(FZ3='Quick Setup'!$Q$45,'Quick Setup'!$Q46,if(FZ3='Quick Setup'!$R$45,'Quick Setup'!$R46,if(FZ3='Quick Setup'!$S$45,'Quick Setup'!$S46,if(FZ3='Quick Setup'!$T$45,'Quick Setup'!$T46,if(FZ3='Quick Setup'!$U$45,'Quick Setup'!$U46,if(FZ3='Quick Setup'!$V$45,'Quick Setup'!$V46,'Quick Setup'!$W46)))))))))))))))))))) -> 4 | GC3: =FQ3 -> 5 | GD3: =FR3 -> -0.05 | GE3: =FS3 -> -0.02 | GF3: =FT3 -> 0 | GG3: =FU3 -> 0.005 | GH3: =FV3 -> 0.01 | GI3: =FW3 -> 0.015 | GJ3: =FX3 -> 0.02 | GK3: =FY3 -> 0.03 | GL3: ='Quick Setup'!S60 -> 0.9 | GM3: =if(GL3='Quick Setup'!$C$31,'Quick Setup'!$C32,if(GL3='Quick Setup'!$D$31,'Quick Setup'!$D32,if(GL3='Quick Setup'!$E$31,'Quick Setup'!$E32,if(GL3='Quick Setup'!$F$31,'Quick Setup'!$F32,if(GL3='Quick Setup'!$G$31,'Quick Setup'!$G32,if(GL3='Quick Setup'!$H$31,'Quick Setup'!$H32,if(GL3='Quick Setup'!$I$31,'Quick Setup'!$I32,if(GL3='Quick Setup'!$J$31,'Quick Setup'!$J32,if(GL3='Quick Setup'!$K$31,'Quick Setup'!$K32,if(GL3='Quick Setup'!$L$31,'Quick Setup'!$L32,if(GL3='Quick Setup'!$M$31,'Quick Setup'!$M32,if(GL3='Quick Setup'!$N$31,'Quick Setup'!$N32,if(GL3='Quick Setup'!$O$31,'Quick Setup'!$O32,if(GL3='Quick Setup'!$P$31,'Quick Setup'!$P32,if(GL3='Quick Setup'!$Q$31,'Quick Setup'!$Q32,if(GL3='Quick Setup'!$R$31,'Quick Setup'!$R32,if(GL3='Quick Setup'!$S$31,'Quick Setup'!$S32,if(GL3='Quick Setup'!$T$31,'Quick Setup'!$T32,if(GL3='Quick Setup'!$U$31,'Quick Setup'!$U32,if(GL3='Quick Setup'!$V$31,'Quick Setup'!$V32,'Quick Setup'!$W32)))))))))))))))))))) -> 1 | GN3: =if(GL3='Quick Setup'!$C$45,'Quick Setup'!$C46,if(GL3='Quick Setup'!$D$45,'Quick Setup'!$D46,if(GL3='Quick Setup'!$E$45,'Quick Setup'!$E46,if(GL3='Quick Setup'!$F$45,'Quick Setup'!$F46,if(GL3='Quick Setup'!$G$45,'Quick Setup'!$G46,if(GL3='Quick Setup'!$H$45,'Quick Setup'!$H46,if(GL3='Quick Setup'!$I$45,'Quick Setup'!$I46,if(GL3='Quick Setup'!$J$45,'Quick Setup'!$J46,if(GL3='Quick Setup'!$K$45,'Quick Setup'!$K46,if(GL3='Quick Setup'!$L$45,'Quick Setup'!$L46,if(GL3='Quick Setup'!$M$45,'Quick Setup'!$M46,if(GL3='Quick Setup'!$N$45,'Quick Setup'!$N46,if(GL3='Quick Setup'!$O$45,'Quick Setup'!$O46,if(GL3='Quick Setup'!$P$45,'Quick Setup'!$P46,if(GL3='Quick Setup'!$Q$45,'Quick Setup'!$Q46,if(GL3='Quick Setup'!$R$45,'Quick Setup'!$R46,if(GL3='Quick Setup'!$S$45,'Quick Setup'!$S46,if(GL3='Quick Setup'!$T$45,'Quick Setup'!$T46,if(GL3='Quick Setup'!$U$45,'Quick Setup'!$U46,if(GL3='Quick Setup'!$V$45,'Quick Setup'!$V46,'Quick Setup'!$W46)))))))))))))))))))) -> 2 | GO3: =GC3 -> 5 | GP3: =GD3 -> -0.05 | GQ3: =GE3 -> -0.02 | GR3: =GF3 -> 0 | GS3: =GG3 -> 0.005 | GT3: =GH3 -> 0.01 | GU3: =GI3 -> 0.015 | GV3: =GJ3 -> 0.02 | GW3: =GK3 -> 0.03 | GX3: ='Quick Setup'!T60 -> 0.85 | GY3: =if(GX3='Quick Setup'!$C$31,'Quick Setup'!$C32,if(GX3='Quick Setup'!$D$31,'Quick Setup'!$D32,if(GX3='Quick Setup'!$E$31,'Quick Setup'!$E32,if(GX3='Quick Setup'!$F$31,'Quick Setup'!$F32,if(GX3='Quick Setup'!$G$31,'Quick Setup'!$G32,if(GX3='Quick Setup'!$H$31,'Quick Setup'!$H32,if(GX3='Quick Setup'!$I$31,'Quick Setup'!$I32,if(GX3='Quick Setup'!$J$31,'Quick Setup'!$J32,if(GX3='Quick Setup'!$K$31,'Quick Setup'!$K32,if(GX3='Quick Setup'!$L$31,'Quick Setup'!$L32,if(GX3='Quick Setup'!$M$31,'Quick Setup'!$M32,if(GX3='Quick Setup'!$N$31,'Quick Setup'!$N32,if(GX3='Quick Setup'!$O$31,'Quick Setup'!$O32,if(GX3='Quick Setup'!$P$31,'Quick Setup'!$P32,if(GX3='Quick Setup'!$Q$31,'Quick Setup'!$Q32,if(GX3='Quick Setup'!$R$31,'Quick Setup'!$R32,if(GX3='Quick Setup'!$S$31,'Quick Setup'!$S32,if(GX3='Quick Setup'!$T$31,'Quick Setup'!$T32,if(GX3='Quick Setup'!$U$31,'Quick Setup'!$U32,if(GX3='Quick Setup'!$V$31,'Quick Setup'!$V32,'Quick Setup'!$W32)))))))))))))))))))) -> 2 | GZ3: =if(GX3='Quick Setup'!$C$45,'Quick Setup'!$C46,if(GX3='Quick Setup'!$D$45,'Quick Setup'!$D46,if(GX3='Quick Setup'!$E$45,'Quick Setup'!$E46,if(GX3='Quick Setup'!$F$45,'Quick Setup'!$F46,if(GX3='Quick Setup'!$G$45,'Quick Setup'!$G46,if(GX3='Quick Setup'!$H$45,'Quick Setup'!$H46,if(GX3='Quick Setup'!$I$45,'Quick Setup'!$I46,if(GX3='Quick Setup'!$J$45,'Quick Setup'!$J46,if(GX3='Quick Setup'!$K$45,'Quick Setup'!$K46,if(GX3='Quick Setup'!$L$45,'Quick Setup'!$L46,if(GX3='Quick Setup'!$M$45,'Quick Setup'!$M46,if(GX3='Quick Setup'!$N$45,'Quick Setup'!$N46,if(GX3='Quick Setup'!$O$45,'Quick Setup'!$O46,if(GX3='Quick Setup'!$P$45,'Quick Setup'!$P46,if(GX3='Quick Setup'!$Q$45,'Quick Setup'!$Q46,if(GX3='Quick Setup'!$R$45,'Quick Setup'!$R46,if(GX3='Quick Setup'!$S$45,'Quick Setup'!$S46,if(GX3='Quick Setup'!$T$45,'Quick Setup'!$T46,if(GX3='Quick Setup'!$U$45,'Quick Setup'!$U46,if(GX3='Quick Setup'!$V$45,'Quick Setup'!$V46,'Quick Setup'!$W46)))))))))))))))))))) -> 4 | HA3: =GO3 -> 5 | HB3: =GP3 -> -0.05 | HC3: =GQ3 -> -0.02 | HD3: =GR3 -> 0 | HE3: =GS3 -> 0.005 | HF3: =GT3 -> 0.01 | HG3: =GU3 -> 0.015 | HH3: =GV3 -> 0.02 | HI3: =GW3 -> 0.03 | HJ3: ='Quick Setup'!U60 -> 0.9 | HK3: =if(HJ3='Quick Setup'!$C$31,'Quick Setup'!$C32,if(HJ3='Quick Setup'!$D$31,'Quick Setup'!$D32,if(HJ3='Quick Setup'!$E$31,'Quick Setup'!$E32,if(HJ3='Quick Setup'!$F$31,'Quick Setup'!$F32,if(HJ3='Quick Setup'!$G$31,'Quick Setup'!$G32,if(HJ3='Quick Setup'!$H$31,'Quick Setup'!$H32,if(HJ3='Quick Setup'!$I$31,'Quick Setup'!$I32,if(HJ3='Quick Setup'!$J$31,'Quick Setup'!$J32,if(HJ3='Quick Setup'!$K$31,'Quick Setup'!$K32,if(HJ3='Quick Setup'!$L$31,'Quick Setup'!$L32,if(HJ3='Quick Setup'!$M$31,'Quick Setup'!$M32,if(HJ3='Quick Setup'!$N$31,'Quick Setup'!$N32,if(HJ3='Quick Setup'!$O$31,'Quick Setup'!$O32,if(HJ3='Quick Setup'!$P$31,'Quick Setup'!$P32,if(HJ3='Quick Setup'!$Q$31,'Quick Setup'!$Q32,if(HJ3='Quick Setup'!$R$31,'Quick Setup'!$R32,if(HJ3='Quick Setup'!$S$31,'Quick Setup'!$S32,if(HJ3='Quick Setup'!$T$31,'Quick Setup'!$T32,if(HJ3='Quick Setup'!$U$31,'Quick Setup'!$U32,if(HJ3='Quick Setup'!$V$31,'Quick Setup'!$V32,'Quick Setup'!$W32)))))))))))))))))))) -> 1 | HL3: =if(HJ3='Quick Setup'!$C$45,'Quick Setup'!$C46,if(HJ3='Quick Setup'!$D$45,'Quick Setup'!$D46,if(HJ3='Quick Setup'!$E$45,'Quick Setup'!$E46,if(HJ3='Quick Setup'!$F$45,'Quick Setup'!$F46,if(HJ3='Quick Setup'!$G$45,'Quick Setup'!$G46,if(HJ3='Quick Setup'!$H$45,'Quick Setup'!$H46,if(HJ3='Quick Setup'!$I$45,'Quick Setup'!$I46,if(HJ3='Quick Setup'!$J$45,'Quick Setup'!$J46,if(HJ3='Quick Setup'!$K$45,'Quick Setup'!$K46,if(HJ3='Quick Setup'!$L$45,'Quick Setup'!$L46,if(HJ3='Quick Setup'!$M$45,'Quick Setup'!$M46,if(HJ3='Quick Setup'!$N$45,'Quick Setup'!$N46,if(HJ3='Quick Setup'!$O$45,'Quick Setup'!$O46,if(HJ3='Quick Setup'!$P$45,'Quick Setup'!$P46,if(HJ3='Quick Setup'!$Q$45,'Quick Setup'!$Q46,if(HJ3='Quick Setup'!$R$45,'Quick Setup'!$R46,if(HJ3='Quick Setup'!$S$45,'Quick Setup'!$S46,if(HJ3='Quick Setup'!$T$45,'Quick Setup'!$T46,if(HJ3='Quick Setup'!$U$45,'Quick Setup'!$U46,if(HJ3='Quick Setup'!$V$45,'Quick Setup'!$V46,'Quick Setup'!$W46)))))))))))))))))))) -> 2 | HM3: =HA3 -> 5 | HN3: =HB3 -> -0.05 | HO3: =HC3 -> -0.02 | HP3: =HD3 -> 0 | HQ3: =HE3 -> 0.005 | HR3: =HF3 -> 0.01 | HS3: =HG3 -> 0.015 | HT3: =HH3 -> 0.02 | HU3: =HI3 -> 0.03 | HV3: ='Quick Setup'!V60 -> 0.95 | HW3: =if(HV3='Quick Setup'!$C$31,'Quick Setup'!$C32,if(HV3='Quick Setup'!$D$31,'Quick Setup'!$D32,if(HV3='Quick Setup'!$E$31,'Quick Setup'!$E32,if(HV3='Quick Setup'!$F$31,'Quick Setup'!$F32,if(HV3='Quick Setup'!$G$31,'Quick Setup'!$G32,if(HV3='Quick Setup'!$H$31,'Quick Setup'!$H32,if(HV3='Quick Setup'!$I$31,'Quick Setup'!$I32,if(HV3='Quick Setup'!$J$31,'Quick Setup'!$J32,if(HV3='Quick Setup'!$K$31,'Quick Setup'!$K32,if(HV3='Quick Setup'!$L$31,'Quick Setup'!$L32,if(HV3='Quick Setup'!$M$31,'Quick Setup'!$M32,if(HV3='Quick Setup'!$N$31,'Quick Setup'!$N32,if(HV3='Quick Setup'!$O$31,'Quick Setup'!$O32,if(HV3='Quick Setup'!$P$31,'Quick Setup'!$P32,if(HV3='Quick Setup'!$Q$31,'Quick Setup'!$Q32,if(HV3='Quick Setup'!$R$31,'Quick Setup'!$R32,if(HV3='Quick Setup'!$S$31,'Quick Setup'!$S32,if(HV3='Quick Setup'!$T$31,'Quick Setup'!$T32,if(HV3='Quick Setup'!$U$31,'Quick Setup'!$U32,if(HV3='Quick Setup'!$V$31,'Quick Setup'!$V32,'Quick Setup'!$W32)))))))))))))))))))) -> 1 | HX3: =if(HV3='Quick Setup'!$C$45,'Quick Setup'!$C46,if(HV3='Quick Setup'!$D$45,'Quick Setup'!$D46,if(HV3='Quick Setup'!$E$45,'Quick Setup'!$E46,if(HV3='Quick Setup'!$F$45,'Quick Setup'!$F46,if(HV3='Quick Setup'!$G$45,'Quick Setup'!$G46,if(HV3='Quick Setup'!$H$45,'Quick Setup'!$H46,if(HV3='Quick Setup'!$I$45,'Quick Setup'!$I46,if(HV3='Quick Setup'!$J$45,'Quick Setup'!$J46,if(HV3='Quick Setup'!$K$45,'Quick Setup'!$K46,if(HV3='Quick Setup'!$L$45,'Quick Setup'!$L46,if(HV3='Quick Setup'!$M$45,'Quick Setup'!$M46,if(HV3='Quick Setup'!$N$45,'Quick Setup'!$N46,if(HV3='Quick Setup'!$O$45,'Quick Setup'!$O46,if(HV3='Quick Setup'!$P$45,'Quick Setup'!$P46,if(HV3='Quick Setup'!$Q$45,'Quick Setup'!$Q46,if(HV3='Quick Setup'!$R$45,'Quick Setup'!$R46,if(HV3='Quick Setup'!$S$45,'Quick Setup'!$S46,if(HV3='Quick Setup'!$T$45,'Quick Setup'!$T46,if(HV3='Quick Setup'!$U$45,'Quick Setup'!$U46,if(HV3='Quick Setup'!$V$45,'Quick Setup'!$V46,'Quick Setup'!$W46)))))))))))))))))))) -> 1 | HY3: =HM3 -> 5 | HZ3: =HN3 -> -0.05 | IA3: =HO3 -> -0.02 | IB3: =HP3 -> 0 | IC3: =HQ3 -> 0.005 | ID3: =HR3 -> 0.01 | IE3: =HS3 -> 0.015 | IF3: =HT3 -> 0.02 | IG3: =HU3 -> 0.03 | IH3: ='Quick Setup'!W60 -> 0.6 | II3: =if(IH3='Quick Setup'!$C$31,'Quick Setup'!$C32,if(IH3='Quick Setup'!$D$31,'Quick Setup'!$D32,if(IH3='Quick Setup'!$E$31,'Quick Setup'!$E32,if(IH3='Quick Setup'!$F$31,'Quick Setup'!$F32,if(IH3='Quick Setup'!$G$31,'Quick Setup'!$G32,if(IH3='Quick Setup'!$H$31,'Quick Setup'!$H32,if(IH3='Quick Setup'!$I$31,'Quick Setup'!$I32,if(IH3='Quick Setup'!$J$31,'Quick Setup'!$J32,if(IH3='Quick Setup'!$K$31,'Quick Setup'!$K32,if(IH3='Quick Setup'!$L$31,'Quick Setup'!$L32,if(IH3='Quick Setup'!$M$31,'Quick Setup'!$M32,if(IH3='Quick Setup'!$N$31,'Quick Setup'!$N32,if(IH3='Quick Setup'!$O$31,'Quick Setup'!$O32,if(IH3='Quick Setup'!$P$31,'Quick Setup'!$P32,if(IH3='Quick Setup'!$Q$31,'Quick Setup'!$Q32,if(IH3='Quick Setup'!$R$31,'Quick Setup'!$R32,if(IH3='Quick Setup'!$S$31,'Quick Setup'!$S32,if(IH3='Quick Setup'!$T$31,'Quick Setup'!$T32,if(IH3='Quick Setup'!$U$31,'Quick Setup'!$U32,if(IH3='Quick Setup'!$V$31,'Quick Setup'!$V32,'Quick Setup'!$W32)))))))))))))))))))) -> 7 | IJ3: =if(IH3='Quick Setup'!$C$45,'Quick Setup'!$C46,if(IH3='Quick Setup'!$D$45,'Quick Setup'!$D46,if(IH3='Quick Setup'!$E$45,'Quick Setup'!$E46,if(IH3='Quick Setup'!$F$45,'Quick Setup'!$F46,if(IH3='Quick Setup'!$G$45,'Quick Setup'!$G46,if(IH3='Quick Setup'!$H$45,'Quick Setup'!$H46,if(IH3='Quick Setup'!$I$45,'Quick Setup'!$I46,if(IH3='Quick Setup'!$J$45,'Quick Setup'!$J46,if(IH3='Quick Setup'!$K$45,'Quick Setup'!$K46,if(IH3='Quick Setup'!$L$45,'Quick Setup'!$L46,if(IH3='Quick Setup'!$M$45,'Quick Setup'!$M46,if(IH3='Quick Setup'!$N$45,'Quick Setup'!$N46,if(IH3='Quick Setup'!$O$45,'Quick Setup'!$O46,if(IH3='Quick Setup'!$P$45,'Quick Setup'!$P46,if(IH3='Quick Setup'!$Q$45,'Quick Setup'!$Q46,if(IH3='Quick Setup'!$R$45,'Quick Setup'!$R46,if(IH3='Quick Setup'!$S$45,'Quick Setup'!$S46,if(IH3='Quick Setup'!$T$45,'Quick Setup'!$T46,if(IH3='Quick Setup'!$U$45,'Quick Setup'!$U46,if(IH3='Quick Setup'!$V$45,'Quick Setup'!$V46,'Quick Setup'!$W46)))))))))))))))))))) -> 14 | IK3: =HY3 -> 5 | IL3: =HZ3 -> -0.05 | IM3: =IA3 -> -0.02 | IN3: =IB3 -> 0 | IO3: =IC3 -> 0.005 | IP3: =ID3 -> 0.01 | IQ3: =IE3 -> 0.015 | IR3: =IF3 -> 0.02 | IS3: =IG3 -> 0.03
