Workbook

Sheet Quick Setup
A1: Rounding | C1: Make a copy (for google drive; recommended) or download this spreadsheet (for other spreadsheet programs). Do not request editing access
A2: 2.5
C4: Main Lifts | D4: Maxes | E4: Single @8 percentage | H4: Sets per week | J4: When above or below set range
C5: Squat | D5: 490 | E5: 0.9 | H5: Lower threshold | I5: Upper threshold | J5: Increases | K5: Decreases
C6: Bench Press | D6: 325 | E6: 0.9 | G6: =C5 -> Squat | H6: 4 | I6: 6 | J6: 0.02 | K6: -0.05
B7: Primary stance | C7: Deadlift | D7: 525 | E7: 0.9 | G7: =C6 -> Bench Press | H7: 4 | I7: 6 | J7: 0.02 | K7: -0.05
C8: OHP | D8: 200 | E8: 0.9 | G8: =C7 -> Deadlift | H8: 4 | I8: 6 | J8: 0.02 | K8: -0.05
G9: =C8 -> OHP | H9: 4 | I9: 6 | J9: 0.02 | K9: -0.05
C10: Variations: Note - if you don't know your max, you can estimate it. When in doubt, estimate low to start with | D10: Maxes | G10: =C11 -> Front Squat | H10: 4 | I10: 6 | J10: 0.02 | K10: -0.05
B11: Squat auxiliary 1 | C11: Front Squat | D11: 420 | E11: 0.9 | G11: =C12 -> Paused Squat | H11: 4 | I11: 6 | J11: 0.02 | K11: -0.05
B12: Squat auxiliary 2 | C12: Paused Squat | D12: 460 | E12: 0.9 | G12: =C13 -> Close Grip Bench | H12: 4 | I12: 6 | J12: 0.02 | K12: -0.05
B13: Bench auxiliary 1 | C13: Close Grip Bench | D13: 310 | E13: 0.9 | G13: =C14 -> Incline Press | H13: 4 | I13: 6 | J13: 0.02 | K13: -0.05
B14: Bench auxiliary 2 | C14: Incline Press | D14: 280 | E14: 0.9 | G14: =C15 -> Sumo Deadlift | H14: 4 | I14: 6 | J14: 0.02 | K14: -0.05
B15: Deadlift auxiliary | C15: Sumo Deadlift | D15: 500 | E15: 0.9 | G15: =C16 -> Push Press | H15: 4 | I15: 6 | J15: 0.02 | K15: -0.05
B16: OHP auxiliary | C16: Push Press | D16: 245 | E16: 0.9
B18: Back exercises
B19: Barbell rows
B20: DB rows
B21: Chest supported rows
B22: T-bar rows
B23: Pull-ups
B24: Chin-ups
B25: Neutral grip pull-ups
B26: Pull-downs
C32: Reps at a given percent
C33: 0.5 | D33: 0.525 | E33: 0.55 | F33: 0.575 | G33: 0.6 | H33: 0.625 | I33: 0.65 | J33: 0.675 | K33: 0.7 | L33: 0.725 | M33: 0.75 | N33: 0.775 | O33: 0.8 | P33: 0.825 | Q33: 0.85 | R33: 0.875 | S33: 0.9 | T33: 0.925 | U33: 0.95 | V33: 0.975 | W33: 1
B34: ='Quick Setup'!C5 -> Squat | C34: 8 | D34: 8 | E34: 8 | F34: 8 | G34: 7 | H34: 7 | I34: 6 | J34: 6 | K34: 5 | L34: 5 | M34: 4 | N34: 4 | O34: 3 | P34: 3 | Q34: 2 | R34: 2 | S34: 1 | T34: 1 | U34: 1 | V34: 1 | W34: 1
B35: ='Quick Setup'!C6 -> Bench Press | C35: =C34 -> 8 | D35: =D34 -> 8 | E35: =E34 -> 8 | F35: =F34 -> 8 | G35: =G34 -> 7 | H35: =H34 -> 7 | I35: =I34 -> 6 | J35: =J34 -> 6 | ... W35: =W34 -> 1
B36: ='Quick Setup'!C7 -> Deadlift | C36: =C35 -> 8 | D36: =D35 -> 8 | E36: =E35 -> 8 | F36: =F35 -> 8 | G36: =G35 -> 7 | H36: =H35 -> 7 | I36: =I35 -> 6 | J36: =J35 -> 6 | ... W36: =W35 -> 1
B37: ='Quick Setup'!C8 -> OHP | C37: =C36 -> 8 | D37: =D36 -> 8 | E37: =E36 -> 8 | F37: =F36 -> 8 | G37: =G36 -> 7 | H37: =H36 -> 7 | I37: =I36 -> 6 | J37: =J36 -> 6 | ... W37: =W36 -> 1
B38: ='Quick Setup'!C11 -> Front Squat | C38: =C37 -> 8 | D38: =D37 -> 8 | E38: =E37 -> 8 | F38: =F37 -> 8 | G38: =G37 -> 7 | H38: =H37 -> 7 | I38: =I37 -> 6 | J38: =J37 -> 6 | ... W38: =W37 -> 1
B39: ='Quick Setup'!C12 -> Paused Squat | C39: =C38 -> 8 | D39: =D38 -> 8 | E39: =E38 -> 8 | F39: =F38 -> 8 | G39: =G38 -> 7 | H39: =H38 -> 7 | I39: =I38 -> 6 | J39: =J38 -> 6 | ... W39: =W38 -> 1
B40: ='Quick Setup'!C13 -> Close Grip Bench | C40: =C39 -> 8 | D40: =D39 -> 8 | E40: =E39 -> 8 | F40: =F39 -> 8 | G40: =G39 -> 7 | H40: =H39 -> 7 | I40: =I39 -> 6 | J40: =J39 -> 6 | ... W40: =W39 -> 1
B41: ='Quick Setup'!C14 -> Incline Press | C41: =C40 -> 8 | D41: =D40 -> 8 | E41: =E40 -> 8 | F41: =F40 -> 8 | G41: =G40 -> 7 | H41: =H40 -> 7 | I41: =I40 -> 6 | J41: =J40 -> 6 | ... W41: =W40 -> 1
B42: ='Quick Setup'!C15 -> Sumo Deadlift | C42: =C41 -> 8 | D42: =D41 -> 8 | E42: =E41 -> 8 | F42: =F41 -> 8 | G42: =G41 -> 7 | H42: =H41 -> 7 | I42: =I41 -> 6 | J42: =J41 -> 6 | ... W42: =W41 -> 1
B43: ='Quick Setup'!C16 -> Push Press | C43: =C42 -> 8 | D43: =D42 -> 8 | E43: =E42 -> 8 | F43: =F42 -> 8 | G43: =G42 -> 7 | H43: =H42 -> 7 | I43: =I42 -> 6 | J43: =J42 -> 6 | ... W43: =W42 -> 1
C46: RIR cutoffs
C47: 0.5 | D47: 0.525 | E47: 0.55 | F47: 0.575 | G47: 0.6 | H47: 0.625 | I47: 0.65 | J47: 0.675 | K47: 0.7 | L47: 0.725 | M47: 0.75 | N47: 0.775 | O47: 0.8 | P47: 0.825 | Q47: 0.85 | R47: 0.875 | S47: 0.9 | T47: 0.925 | U47: 0.95 | V47: 0.975 | W47: 1
B48: ='Quick Setup'!C5 -> Squat | C48: 5 | D48: 5 | E48: 5 | F48: 5 | G48: 4 | H48: 4 | I48: 4 | J48: 4 | K48: 3 | L48: 3 | M48: 3 | N48: 3 | O48: 2 | P48: 2 | Q48: 2 | R48: 2 | S48: 1 | T48: 1 | U48: 1 | V48: 0 | W48: 0
B49: ='Quick Setup'!C6 -> Bench Press | C49: 5 | D49: 5 | E49: 5 | F49: 5 | G49: 4 | H49: 4 | I49: 4 | J49: 4 | K49: 3 | L49: 3 | M49: 3 | N49: 3 | O49: 2 | P49: 2 | Q49: 2 | R49: 2 | S49: 1 | T49: 1 | U49: 1 | V49: 0 | W49: 0
...

Sheet Setup
A1: Week | B1: 1 | I1: =B1+1 -> 2 | P1: =I1+1 -> 3 | W1: =P1+1 -> 4 | AD1: =W1+1 -> 5 | AK1: =AD1+1 -> 6 | AR1: =AK1+1 -> 7 | AY1: =AR1+1 -> 8 | BF1: =AY1+1 -> 9 | BM1: =BF1+1 -> 10 | BT1: =BM1+1 -> 11 | CA1: =BT1+1 -> 12 | CH1: =CA1+1 -> 13 | CO1: =CH1+1 -> 14 | CV1: =CO1+1 -> 15 | DC1: =CV1+1 -> 16 | DJ1: =DC1+1 -> 17 | DQ1: =DJ1+1 -> 18 | DX1: =DQ1+1 -> 19 | EE1: =DX1+1 -> 20 | EL1: =EE1+1 -> 21
E2: Sets per week | G2: When above or below set range | L2: Sets per week | N2: When above or below set range | S2: Sets per week | U2: When above or below set range | Z2: Sets per week | AB2: When above or below set range | AG2: Sets per week | AI2: When above or below set range | AN2: Sets per week | AP2: When above or below set range | AU2: Sets per week | AW2: When above or below set range | BB2: Sets per week | BD2: When above or below set range | BI2: Sets per week | BK2: When above or below set range | BP2: Sets per week | BR2: When above or below set range | BW2: Sets per week | BY2: When above or below set range | CD2: Sets per week | CF2: When above or below set range | CK2: Sets per week | CM2: When above or below set range | CR2: Sets per week | CT2: When above or below set range | CY2: Sets per week | DA2: When above or below set range | DF2: Sets per week | DH2: When above or below set range | DM2: Sets per week | DO2: When above or below set range | DT2: Sets per week | DV2: When above or below set range | EA2: Sets per week | EC2: When above or below set range | EH2: Sets per week | EJ2: When above or below set range | EO2: Sets per week | EQ2: When above or below set range
A3: Lift | B3: Intensity | C3: Reps per set | D3: RIR Cutoff | E3: Lower threshold | F3: Upper threshold | G3: Increases | H3: Decreases | I3: Intensity | J3: Reps per set | K3: RIR Cutoff | L3: Lower threshold | M3: Upper threshold | N3: Increases | O3: Decreases | P3: Intensity | Q3: Reps per set | R3: RIR Cutoff | S3: Lower threshold | T3: Upper threshold | U3: Increases | V3: Decreases | W3: Intensity | X3: Reps per set | Y3: RIR Cutoff | Z3: Lower threshold | AA3: Upper threshold | AB3: Increases | AC3: Decreases | AD3: Intensity | AE3: Reps per set | AF3: RIR Cutoff | AG3: Lower threshold | AH3: Upper threshold | AI3: Increases | AJ3: Decreases | AK3: Intensity | AL3: Reps per set | AM3: RIR Cutoff | AN3: Lower threshold | AO3: Upper threshold | AP3: Increases | AQ3: Decreases | AR3: Intensity | AS3: Reps per set | AT3: RIR Cutoff | AU3: Lower threshold | AV3: Upper threshold | AW3: Increases | AX3: Decreases | AY3: Intensity | AZ3: Reps per set | BA3: RIR Cutoff | BB3: Lower threshold | BC3: Upper threshold | BD3: Increases | BE3: Decreases | BF3: Intensity | BG3: Reps per set | BH3: RIR Cutoff | BI3: Lower threshold | BJ3: Upper threshold | BK3: Increases | BL3: Decreases | BM3: Intensity | BN3: Reps per set | BO3: RIR Cutoff | BP3: Lower threshold | BQ3: Upper threshold | BR3: Increases | BS3: Decreases | BT3: Intensity | BU3: Reps per set | BV3: RIR Cutoff | BW3: Lower threshold | BX3: Upper threshold | BY3: Increases | BZ3: Decreases | CA3: Intensity | CB3: Reps per set | CC3: RIR Cutoff | CD3: Lower threshold | CE3: Upper threshold | CF3: Increases | CG3: Decreases | CH3: Intensity | CI3: Reps per set | CJ3: RIR Cutoff | CK3: Lower threshold | CL3: Upper threshold | CM3: Increases | CN3: Decreases | CO3: Intensity | CP3: Reps per set | CQ3: RIR Cutoff | CR3: Lower threshold | CS3: Upper threshold | CT3: Increases | CU3: Decreases | CV3: Intensity | CW3: Reps per set | CX3: RIR Cutoff | CY3: Lower threshold | CZ3: Upper threshold | DA3: Increases | DB3: Decreases | DC3: Intensity | DD3: Reps per set | DE3: RIR Cutoff | DF3: Lower threshold | DG3: Upper threshold | DH3: Increases | DI3: Decreases | DJ3: Intensity | DK3: Reps per set | DL3: RIR Cutoff | DM3: Lower threshold | DN3: Upper threshold | DO3: Increases | DP3: Decreases | DQ3: Intensity | DR3: Reps per set | DS3: RIR Cutoff | DT3: Lower threshold | DU3: Upper threshold | DV3: Increases | DW3: Decreases | DX3: Intensity | DY3: Reps per set | DZ3: RIR Cutoff | EA3: Lower threshold | EB3: Upper threshold | EC3: Increases | ED3: Decreases | EE3: Intensity | EF3: Reps per set | EG3: RIR Cutoff | EH3: Lower threshold | EI3: Upper threshold | EJ3: Increases | EK3: Decreases | EL3: Intensity | EM3: Reps per set | EN3: RIR Cutoff | EO3: Lower threshold | EP3: Upper threshold | EQ3: Increases | ER3: Decreases
A4: ='Quick Setup'!C5 -> Squat | B4: ='Quick Setup'!C61 -> 0.7 | C4: =if(B4='Quick Setup'!$C$33,'Quick Setup'!$C34,if(B4='Quick Setup'!$D$33,'Quick Setup'!$D34,if(B4='Quick Setup'!$E$33,'Quick Setup'!$E34,if(B4='Quick Setup'!$F$33,'Quick Setup'!$F34,if(B4='Quick Setup'!$G$33,'Quick Setup'!$G34,if(B4='Quick Setup'!$H$33,'Quick Setup'!$H34,if(B4='Quick Setup'!$I$33,'Quick Setup'!$I34,if(B4='Quick Setup'!$J$33,'Quick Setup'!$J34,if(B4='Quick Setup'!$K$33,'Quick Setup'!$K34,if(B4='Quick Setup'!$L$33,'Quick Setup'!$L34,if(B4='Quick Setup'!$M$33,'Quick Setup'!$M34,if(B4='Quick Setup'!$N$33,'Quick Setup'!$N34,if(B4='Quick Setup'!$O$33,'Quick Setup'!$O34,if(B4='Quick Setup'!$P$33,'Quick Setup'!$P34,if(B4='Quick Setup'!$Q$33,'Quick Setup'!$Q34,if(B4='Quick Setup'!$R$33,'Quick Setup'!$R34,if(B4='Quick Setup'!$S$33,'Quick Setup'!$S34,if(B4='Quick Setup'!$T$33,'Quick Setup'!$T34,if(B4='Quick Setup'!$U$33,'Quick Setup'!$U34,if(B4='Quick Setup'!$V$33,'Quick Setup'!$V34,'Quick Setup'!W34)))))))))))))))))))) -> 5 | D4: =if(B4='Quick Setup'!$C$47,'Quick Setup'!$C48,if(B4='Quick Setup'!$D$47,'Quick Setup'!$D48,if(B4='Quick Setup'!$E$47,'Quick Setup'!$E48,if(B4='Quick Setup'!$F$47,'Quick Setup'!$F48,if(B4='Quick Setup'!$G$47,'Quick Setup'!$G48,if(B4='Quick Setup'!$H$47,'Quick Setup'!$H48,if(B4='Quick Setup'!$I$47,'Quick Setup'!$I48,if(B4='Quick Setup'!$J$47,'Quick Setup'!$J48,if(B4='Quick Setup'!$K$47,'Quick Setup'!$K48,if(B4='Quick Setup'!$L$47,'Quick Setup'!$L48,if(B4='Quick Setup'!$M$47,'Quick Setup'!$M48,if(B4='Quick Setup'!$N$47,'Quick Setup'!$N48,if(B4='Quick Setup'!$O$47,'Quick Setup'!$O48,if(B4='Quick Setup'!$P$47,'Quick Setup'!$P48,if(B4='Quick Setup'!$Q$47,'Quick Setup'!$Q48,if(B4='Quick Setup'!$R$47,'Quick Setup'!$R48,if(B4='Quick Setup'!$S$47,'Quick Setup'!$S48,if(B4='Quick Setup'!$T$47,'Quick Setup'!$T48,if(B4='Quick Setup'!$U$47,'Quick Setup'!$U48,if(B4='Quick Setup'!$V$47,'Quick Setup'!$V48,if(B4='Quick Setup'!$W$47,'Quick Setup'!$W48))))))))))))))))))))) -> 3 | E4: ='Quick Setup'!H6 -> 4 | F4: ='Quick Setup'!I6 -> 6 | G4: ='Quick Setup'!J6 -> 0.02 | H4: ='Quick Setup'!K6 -> -0.05 | I4: ='Quick Setup'!D61 -> 0.75 | J4: =if(I4='Quick Setup'!$C$33,'Quick Setup'!$C34,if(I4='Quick Setup'!$D$33,'Quick Setup'!$D34,if(I4='Quick Setup'!$E$33,'Quick Setup'!$E34,if(I4='Quick Setup'!$F$33,'Quick Setup'!$F34,if(I4='Quick Setup'!$G$33,'Quick Setup'!$G34,if(I4='Quick Setup'!$H$33,'Quick Setup'!$H34,if(I4='Quick Setup'!$I$33,'Quick Setup'!$I34,if(I4='Quick Setup'!$J$33,'Quick Setup'!$J34,if(I4='Quick Setup'!$K$33,'Quick Setup'!$K34,if(I4='Quick Setup'!$L$33,'Quick Setup'!$L34,if(I4='Quick Setup'!$M$33,'Quick Setup'!$M34,if(I4='Quick Setup'!$N$33,'Quick Setup'!$N34,if(I4='Quick Setup'!$O$33,'Quick Setup'!$O34,if(I4='Quick Setup'!$P$33,'Quick Setup'!$P34,if(I4='Quick Setup'!$Q$33,'Quick Setup'!$Q34,if(I4='Quick Setup'!$R$33,'Quick Setup'!$R34,if(I4='Quick Setup'!$S$33,'Quick Setup'!$S34,if(I4='Quick Setup'!$T$33,'Quick Setup'!$T34,if(I4='Quick Setup'!$U$33,'Quick Setup'!$U34,if(I4='Quick Setup'!$V$33,'Quick Setup'!$V34,'2x'!AD5)))))))))))))))))))) -> 4 | K4: =if(I4='Quick Setup'!$C$47,'Quick Setup'!$C48,if(I4='Quick Setup'!$D$47,'Quick Setup'!$D48,if(I4='Quick Setup'!$E$47,'Quick Setup'!$E48,if(I4='Quick Setup'!$F$47,'Quick Setup'!$F48,if(I4='Quick Setup'!$G$47,'Quick Setup'!$G48,if(I4='Quick Setup'!$H$47,'Quick Setup'!$H48,if(I4='Quick Setup'!$I$47,'Quick Setup'!$I48,if(I4='Quick Setup'!$J$47,'Quick Setup'!$J48,if(I4='Quick Setup'!$K$47,'Quick Setup'!$K48,if(I4='Quick Setup'!$L$47,'Quick Setup'!$L48,if(I4='Quick Setup'!$M$47,'Quick Setup'!$M48,if(I4='Quick Setup'!$N$47,'Quick Setup'!$N48,if(I4='Quick Setup'!$O$47,'Quick Setup'!$O48,if(I4='Quick Setup'!$P$47,'Quick Setup'!$P48,if(I4='Quick Setup'!$Q$47,'Quick Setup'!$Q48,if(I4='Quick Setup'!$R$47,'Quick Setup'!$R48,if(I4='Quick Setup'!$S$47,'Quick Setup'!$S48,if(I4='Quick Setup'!$T$47,'Quick Setup'!$T48,if(I4='Quick Setup'!$U$47,'Quick Setup'!$U48,if(I4='Quick Setup'!$V$47,'Quick Setup'!$V48,if(I4='Quick Setup'!$W$47,'Quick Setup'!$W48))))))))))))))))))))) -> 3 | L4: =E4 -> 4 | M4: =F4 -> 6 | N4: =G4 -> 0.02 | O4: =H4 -> -0.05 | P4: ='Quick Setup'!E61 -> 0.8 | Q4: =if(P4='Quick Setup'!$C$33,'Quick Setup'!$C34,if(P4='Quick Setup'!$D$33,'Quick Setup'!$D34,if(P4='Quick Setup'!$E$33,'Quick Setup'!$E34,if(P4='Quick Setup'!$F$33,'Quick Setup'!$F34,if(P4='Quick Setup'!$G$33,'Quick Setup'!$G34,if(P4='Quick Setup'!$H$33,'Quick Setup'!$H34,if(P4='Quick Setup'!$I$33,'Quick Setup'!$I34,if(P4='Quick Setup'!$J$33,'Quick Setup'!$J34,if(P4='Quick Setup'!$K$33,'Quick Setup'!$K34,if(P4='Quick Setup'!$L$33,'Quick Setup'!$L34,if(P4='Quick Setup'!$M$33,'Quick Setup'!$M34,if(P4='Quick Setup'!$N$33,'Quick Setup'!$N34,if(P4='Quick Setup'!$O$33,'Quick Setup'!$O34,if(P4='Quick Setup'!$P$33,'Quick Setup'!$P34,if(P4='Quick Setup'!$Q$33,'Quick Setup'!$Q34,if(P4='Quick Setup'!$R$33,'Quick Setup'!$R34,if(P4='Quick Setup'!$S$33,'Quick Setup'!$S34,if(P4='Quick Setup'!$T$33,'Quick Setup'!$T34,if(P4='Quick Setup'!$U$33,'Quick Setup'!$U34,if(P4='Quick Setup'!$V$33,'Quick Setup'!$V34,'2x'!AK5)))))))))))))))))))) -> 3 | R4: =if(P4='Quick Setup'!$C$47,'Quick Setup'!$C48,if(P4='Quick Setup'!$D$47,'Quick Setup'!$D48,if(P4='Quick Setup'!$E$47,'Quick Setup'!$E48,if(P4='Quick Setup'!$F$47,'Quick Setup'!$F48,if(P4='Quick Setup'!$G$47,'Quick Setup'!$G48,if(P4='Quick Setup'!$H$47,'Quick Setup'!$H48,if(P4='Quick Setup'!$I$47,'Quick Setup'!$I48,if(P4='Quick Setup'!$J$47,'Quick Setup'!$J48,if(P4='Quick Setup'!$K$47,'Quick Setup'!$K48,if(P4='Quick Setup'!$L$47,'Quick Setup'!$L48,if(P4='Quick Setup'!$M$47,'Quick Setup'!$M48,if(P4='Quick Setup'!$N$47,'Quick Setup'!$N48,if(P4='Quick Setup'!$O$47,'Quick Setup'!$O48,if(P4='Quick Setup'!$P$47,'Quick Setup'!$P48,if(P4='Quick Setup'!$Q$47,'Quick Setup'!$Q48,if(P4='Quick Setup'!$R$47,'Quick Setup'!$R48,if(P4='Quick Setup'!$S$47,'Quick Setup'!$S48,if(P4='Quick Setup'!$T$47,'Quick Setup'!$T48,if(P4='Quick Setup'!$U$47,'Quick Setup'!$U48,if(P4='Quick Setup'!$V$47,'Quick Setup'!$V48,if(P4='Quick Setup'!$W$47,'Quick Setup'!$W48))))))))))))))))))))) -> 2 | S4: =L4 -> 4 | T4: =M4 -> 6 | U4: =N4 -> 0.02 | V4: =O4 -> -0.05 | W4: ='Quick Setup'!F61 -> 0.725 | X4: =if(W4='Quick Setup'!$C$33,'Quick Setup'!$C34,if(W4='Quick Setup'!$D$33,'Quick Setup'!$D34,if(W4='Quick Setup'!$E$33,'Quick Setup'!$E34,if(W4='Quick Setup'!$F$33,'Quick Setup'!$F34,if(W4='Quick Setup'!$G$33,'Quick Setup'!$G34,if(W4='Quick Setup'!$H$33,'Quick Setup'!$H34,if(W4='Quick Setup'!$I$33,'Quick Setup'!$I34,if(W4='Quick Setup'!$J$33,'Quick Setup'!$J34,if(W4='Quick Setup'!$K$33,'Quick Setup'!$K34,if(W4='Quick Setup'!$L$33,'Quick Setup'!$L34,if(W4='Quick Setup'!$M$33,'Quick Setup'!$M34,if(W4='Quick Setup'!$N$33,'Quick Setup'!$N34,if(W4='Quick Setup'!$O$33,'Quick Setup'!$O34,if(W4='Quick Setup'!$P$33,'Quick Setup'!$P34,if(W4='Quick Setup'!$Q$33,'Quick Setup'!$Q34,if(W4='Quick Setup'!$R$33,'Quick Setup'!$R34,if(W4='Quick Setup'!$S$33,'Quick Setup'!$S34,if(W4='Quick Setup'!$T$33,'Quick Setup'!$T34,if(W4='Quick Setup'!$U$33,'Quick Setup'!$U34,if(W4='Quick Setup'!$V$33,'Quick Setup'!$V34,'2x'!AR5)))))))))))))))))))) -> 5 | Y4: =if(W4='Quick Setup'!$C$47,'Quick Setup'!$C48,if(W4='Quick Setup'!$D$47,'Quick Setup'!$D48,if(W4='Quick Setup'!$E$47,'Quick Setup'!$E48,if(W4='Quick Setup'!$F$47,'Quick Setup'!$F48,if(W4='Quick Setup'!$G$47,'Quick Setup'!$G48,if(W4='Quick Setup'!$H$47,'Quick Setup'!$H48,if(W4='Quick Setup'!$I$47,'Quick Setup'!$I48,if(W4='Quick Setup'!$J$47,'Quick Setup'!$J48,if(W4='Quick Setup'!$K$47,'Quick Setup'!$K48,if(W4='Quick Setup'!$L$47,'Quick Setup'!$L48,if(W4='Quick Setup'!$M$47,'Quick Setup'!$M48,if(W4='Quick Setup'!$N$47,'Quick Setup'!$N48,if(W4='Quick Setup'!$O$47,'Quick Setup'!$O48,if(W4='Quick Setup'!$P$47,'Quick Setup'!$P48,if(W4='Quick Setup'!$Q$47,'Quick Setup'!$Q48,if(W4='Quick Setup'!$R$47,'Quick Setup'!$R48,if(W4='Quick Setup'!$S$47,'Quick Setup'!$S48,if(W4='Quick Setup'!$T$47,'Quick Setup'!$T48,if(W4='Quick Setup'!$U$47,'Quick Setup'!$U48,if(W4='Quick Setup'!$V$47,'Quick Setup'!$V48,if(W4='Quick Setup'!$W$47,'Quick Setup'!$W48))))))))))))))))))))) -> 3 | Z4: =S4 -> 4 | AA4: =T4 -> 6 | AB4: =U4 -> 0.02 | AC4: =V4 -> -0.05 | AD4: ='Quick Setup'!G61 -> 0.775 | AE4: =if(AD4='Quick Setup'!$C$33,'Quick Setup'!$C34,if(AD4='Quick Setup'!$D$33,'Quick Setup'!$D34,if(AD4='Quick Setup'!$E$33,'Quick Setup'!$E34,if(AD4='Quick Setup'!$F$33,'Quick Setup'!$F34,if(AD4='Quick Setup'!$G$33,'Quick Setup'!$G34,if(AD4='Quick Setup'!$H$33,'Quick Setup'!$H34,if(AD4='Quick Setup'!$I$33,'Quick Setup'!$I34,if(AD4='Quick Setup'!$J$33,'Quick Setup'!$J34,if(AD4='Quick Setup'!$K$33,'Quick Setup'!$K34,if(AD4='Quick Setup'!$L$33,'Quick Setup'!$L34,if(AD4='Quick Setup'!$M$33,'Quick Setup'!$M34,if(AD4='Quick Setup'!$N$33,'Quick Setup'!$N34,if(AD4='Quick Setup'!$O$33,'Quick Setup'!$O34,if(AD4='Quick Setup'!$P$33,'Quick Setup'!$P34,if(AD4='Quick Setup'!$Q$33,'Quick Setup'!$Q34,if(AD4='Quick Setup'!$R$33,'Quick Setup'!$R34,if(AD4='Quick Setup'!$S$33,'Quick Setup'!$S34,if(AD4='Quick Setup'!$T$33,'Quick Setup'!$T34,if(AD4='Quick Setup'!$U$33,'Quick Setup'!$U34,if(AD4='Quick Setup'!$V$33,'Quick Setup'!$V34,'2x'!AY5)))))))))))))))))))) -> 4 | AF4: =if(AD4='Quick Setup'!$C$47,'Quick Setup'!$C48,if(AD4='Quick Setup'!$D$47,'Quick Setup'!$D48,if(AD4='Quick Setup'!$E$47,'Quick Setup'!$E48,if(AD4='Quick Setup'!$F$47,'Quick Setup'!$F48,if(AD4='Quick Setup'!$G$47,'Quick Setup'!$G48,if(AD4='Quick Setup'!$H$47,'Quick Setup'!$H48,if(AD4='Quick Setup'!$I$47,'Quick Setup'!$I48,if(AD4='Quick Setup'!$J$47,'Quick Setup'!$J48,if(AD4='Quick Setup'!$K$47,'Quick Setup'!$K48,if(AD4='Quick Setup'!$L$47,'Quick Setup'!$L48,if(AD4='Quick Setup'!$M$47,'Quick Setup'!$M48,if(AD4='Quick Setup'!$N$47,'Quick Setup'!$N48,if(AD4='Quick Setup'!$O$47,'Quick Setup'!$O48,if(AD4='Quick Setup'!$P$47,'Quick Setup'!$P48,if(AD4='Quick Setup'!$Q$47,'Quick Setup'!$Q48,if(AD4='Quick Setup'!$R$47,'Quick Setup'!$R48,if(AD4='Quick Setup'!$S$47,'Quick Setup'!$S48,if(AD4='Quick Setup'!$T$47,'Quick Setup'!$T48,if(AD4='Quick Setup'!$U$47,'Quick Setup'!$U48,if(AD4='Quick Setup'!$V$47,'Quick Setup'!$V48,if(AD4='Quick Setup'!$W$47,'Quick Setup'!$W48))))))))))))))))))))) -> 3 | AG4: =Z4 -> 4 | AH4: =AA4 -> 6 | AI4: =AB4 -> 0.02 | AJ4: =AC4 -> -0.05 | AK4: ='Quick Setup'!H61 -> 0.825 | AL4: =if(AK4='Quick Setup'!$C$33,'Quick Setup'!$C34,if(AK4='Quick Setup'!$D$33,'Quick Setup'!$D34,if(AK4='Quick Setup'!$E$33,'Quick Setup'!$E34,if(AK4='Quick Setup'!$F$33,'Quick Setup'!$F34,if(AK4='Quick Setup'!$G$33,'Quick Setup'!$G34,if(AK4='Quick Setup'!$H$33,'Quick Setup'!$H34,if(AK4='Quick Setup'!$I$33,'Quick Setup'!$I34,if(AK4='Quick Setup'!$J$33,'Quick Setup'!$J34,if(AK4='Quick Setup'!$K$33,'Quick Setup'!$K34,if(AK4='Quick Setup'!$L$33,'Quick Setup'!$L34,if(AK4='Quick Setup'!$M$33,'Quick Setup'!$M34,if(AK4='Quick Setup'!$N$33,'Quick Setup'!$N34,if(AK4='Quick Setup'!$O$33,'Quick Setup'!$O34,if(AK4='Quick Setup'!$P$33,'Quick Setup'!$P34,if(AK4='Quick Setup'!$Q$33,'Quick Setup'!$Q34,if(AK4='Quick Setup'!$R$33,'Quick Setup'!$R34,if(AK4='Quick Setup'!$S$33,'Quick Setup'!$S34,if(AK4='Quick Setup'!$T$33,'Quick Setup'!$T34,if(AK4='Quick Setup'!$U$33,'Quick Setup'!$U34,if(AK4='Quick Setup'!$V$33,'Quick Setup'!$V34,'2x'!BF5)))))))))))))))))))) -> 3 | AM4: =if(AK4='Quick Setup'!$C$47,'Quick Setup'!$C48,if(AK4='Quick Setup'!$D$47,'Quick Setup'!$D48,if(AK4='Quick Setup'!$E$47,'Quick Setup'!$E48,if(AK4='Quick Setup'!$F$47,'Quick Setup'!$F48,if(AK4='Quick Setup'!$G$47,'Quick Setup'!$G48,if(AK4='Quick Setup'!$H$47,'Quick Setup'!$H48,if(AK4='Quick Setup'!$I$47,'Quick Setup'!$I48,if(AK4='Quick Setup'!$J$47,'Quick Setup'!$J48,if(AK4='Quick Setup'!$K$47,'Quick Setup'!$K48,if(AK4='Quick Setup'!$L$47,'Quick Setup'!$L48,if(AK4='Quick Setup'!$M$47,'Quick Setup'!$M48,if(AK4='Quick Setup'!$N$47,'Quick Setup'!$N48,if(AK4='Quick Setup'!$O$47,'Quick Setup'!$O48,if(AK4='Quick Setup'!$P$47,'Quick Setup'!$P48,if(AK4='Quick Setup'!$Q$47,'Quick Setup'!$Q48,if(AK4='Quick Setup'!$R$47,'Quick Setup'!$R48,if(AK4='Quick Setup'!$S$47,'Quick Setup'!$S48,if(AK4='Quick Setup'!$T$47,'Quick Setup'!$T48,if(AK4='Quick Setup'!$U$47,'Quick Setup'!$U48,if(AK4='Quick Setup'!$V$47,'Quick Setup'!$V48,if(AK4='Quick Setup'!$W$47,'Quick Setup'!$W48))))))))))))))))))))) -> 2 | AN4: =AG4 -> 4 | AO4: =AH4 -> 6 | AP4: =AI4 -> 0.02 | AQ4: =AJ4 -> -0.05 | AR4: ='Quick Setup'!I61 -> 0.6 | AS4: =if(AR4='Quick Setup'!$C$33,'Quick Setup'!$C34,if(AR4='Quick Setup'!$D$33,'Quick Setup'!$D34,if(AR4='Quick Setup'!$E$33,'Quick Setup'!$E34,if(AR4='Quick Setup'!$F$33,'Quick Setup'!$F34,if(AR4='Quick Setup'!$G$33,'Quick Setup'!$G34,if(AR4='Quick Setup'!$H$33,'Quick Setup'!$H34,if(AR4='Quick Setup'!$I$33,'Quick Setup'!$I34,if(AR4='Quick Setup'!$J$33,'Quick Setup'!$J34,if(AR4='Quick Setup'!$K$33,'Quick Setup'!$K34,if(AR4='Quick Setup'!$L$33,'Quick Setup'!$L34,if(AR4='Quick Setup'!$M$33,'Quick Setup'!$M34,if(AR4='Quick Setup'!$N$33,'Quick Setup'!$N34,if(AR4='Quick Setup'!$O$33,'Quick Setup'!$O34,if(AR4='Quick Setup'!$P$33,'Quick Setup'!$P34,if(AR4='Quick Setup'!$Q$33,'Quick Setup'!$Q34,if(AR4='Quick Setup'!$R$33,'Quick Setup'!$R34,if(AR4='Quick Setup'!$S$33,'Quick Setup'!$S34,if(AR4='Quick Setup'!$T$33,'Quick Setup'!$T34,if(AR4='Quick Setup'!$U$33,'Quick Setup'!$U34,if(AR4='Quick Setup'!$V$33,'Quick Setup'!$V34,'2x'!BM5)))))))))))))))))))) -> 7 | AT4: =if(AR4='Quick Setup'!$C$47,'Quick Setup'!$C48,if(AR4='Quick Setup'!$D$47,'Quick Setup'!$D48,if(AR4='Quick Setup'!$E$47,'Quick Setup'!$E48,if(AR4='Quick Setup'!$F$47,'Quick Setup'!$F48,if(AR4='Quick Setup'!$G$47,'Quick Setup'!$G48,if(AR4='Quick Setup'!$H$47,'Quick Setup'!$H48,if(AR4='Quick Setup'!$I$47,'Quick Setup'!$I48,if(AR4='Quick Setup'!$J$47,'Quick Setup'!$J48,if(AR4='Quick Setup'!$K$47,'Quick Setup'!$K48,if(AR4='Quick Setup'!$L$47,'Quick Setup'!$L48,if(AR4='Quick Setup'!$M$47,'Quick Setup'!$M48,if(AR4='Quick Setup'!$N$47,'Quick Setup'!$N48,if(AR4='Quick Setup'!$O$47,'Quick Setup'!$O48,if(AR4='Quick Setup'!$P$47,'Quick Setup'!$P48,if(AR4='Quick Setup'!$Q$47,'Quick Setup'!$Q48,if(AR4='Quick Setup'!$R$47,'Quick Setup'!$R48,if(AR4='Quick Setup'!$S$47,'Quick Setup'!$S48,if(AR4='Quick Setup'!$T$47,'Quick Setup'!$T48,if(AR4='Quick Setup'!$U$47,'Quick Setup'!$U48,if(AR4='Quick Setup'!$V$47,'Quick Setup'!$V48,if(AR4='Quick Setup'!$W$47,'Quick Setup'!$W48))))))))))))))))))))) -> 4 | AU4: =AN4 -> 4 | AV4: =AO4 -> 6 | AW4: =AP4 -> 0.02 | AX4: =AQ4 -> -0.05 | AY4: ='Quick Setup'!J61 -> 0.75 | AZ4: =if(AY4='Quick Setup'!$C$33,'Quick Setup'!$C34,if(AY4='Quick Setup'!$D$33,'Quick Setup'!$D34,if(AY4='Quick Setup'!$E$33,'Quick Setup'!$E34,if(AY4='Quick Setup'!$F$33,'Quick Setup'!$F34,if(AY4='Quick Setup'!$G$33,'Quick Setup'!$G34,if(AY4='Quick Setup'!$H$33,'Quick Setup'!$H34,if(AY4='Quick Setup'!$I$33,'Quick Setup'!$I34,if(AY4='Quick Setup'!$J$33,'Quick Setup'!$J34,if(AY4='Quick Setup'!$K$33,'Quick Setup'!$K34,if(AY4='Quick Setup'!$L$33,'Quick Setup'!$L34,if(AY4='Quick Setup'!$M$33,'Quick Setup'!$M34,if(AY4='Quick Setup'!$N$33,'Quick Setup'!$N34,if(AY4='Quick Setup'!$O$33,'Quick Setup'!$O34,if(AY4='Quick Setup'!$P$33,'Quick Setup'!$P34,if(AY4='Quick Setup'!$Q$33,'Quick Setup'!$Q34,if(AY4='Quick Setup'!$R$33,'Quick Setup'!$R34,if(AY4='Quick Setup'!$S$33,'Quick Setup'!$S34,if(AY4='Quick Setup'!$T$33,'Quick Setup'!$T34,if(AY4='Quick Setup'!$U$33,'Quick Setup'!$U34,if(AY4='Quick Setup'!$V$33,'Quick Setup'!$V34,'2x'!BT5)))))))))))))))))))) -> 4 | BA4: =if(AY4='Quick Setup'!$C$47,'Quick Setup'!$C48,if(AY4='Quick Setup'!$D$47,'Quick Setup'!$D48,if(AY4='Quick Setup'!$E$47,'Quick Setup'!$E48,if(AY4='Quick Setup'!$F$47,'Quick Setup'!$F48,if(AY4='Quick Setup'!$G$47,'Quick Setup'!$G48,if(AY4='Quick Setup'!$H$47,'Quick Setup'!$H48,if(AY4='Quick Setup'!$I$47,'Quick Setup'!$I48,if(AY4='Quick Setup'!$J$47,'Quick Setup'!$J48,if(AY4='Quick Setup'!$K$47,'Quick Setup'!$K48,if(AY4='Quick Setup'!$L$47,'Quick Setup'!$L48,if(AY4='Quick Setup'!$M$47,'Quick Setup'!$M48,if(AY4='Quick Setup'!$N$47,'Quick Setup'!$N48,if(AY4='Quick Setup'!$O$47,'Quick Setup'!$O48,if(AY4='Quick Setup'!$P$47,'Quick Setup'!$P48,if(AY4='Quick Setup'!$Q$47,'Quick Setup'!$Q48,if(AY4='Quick Setup'!$R$47,'Quick Setup'!$R48,if(AY4='Quick Setup'!$S$47,'Quick Setup'!$S48,if(AY4='Quick Setup'!$T$47,'Quick Setup'!$T48,if(AY4='Quick Setup'!$U$47,'Quick Setup'!$U48,if(AY4='Quick Setup'!$V$47,'Quick Setup'!$V48,if(AY4='Quick Setup'!$W$47,'Quick Setup'!$W48))))))))))))))))))))) -> 3 | BB4: =AU4 -> 4 | BC4: =AV4 -> 6 | BD4: =AW4 -> 0.02 | BE4: =AX4 -> -0.05 | BF4: ='Quick Setup'!K61 -> 0.8 | BG4: =if(BF4='Quick Setup'!$C$33,'Quick Setup'!$C34,if(BF4='Quick Setup'!$D$33,'Quick Setup'!$D34,if(BF4='Quick Setup'!$E$33,'Quick Setup'!$E34,if(BF4='Quick Setup'!$F$33,'Quick Setup'!$F34,if(BF4='Quick Setup'!$G$33,'Quick Setup'!$G34,if(BF4='Quick Setup'!$H$33,'Quick Setup'!$H34,if(BF4='Quick Setup'!$I$33,'Quick Setup'!$I34,if(BF4='Quick Setup'!$J$33,'Quick Setup'!$J34,if(BF4='Quick Setup'!$K$33,'Quick Setup'!$K34,if(BF4='Quick Setup'!$L$33,'Quick Setup'!$L34,if(BF4='Quick Setup'!$M$33,'Quick Setup'!$M34,if(BF4='Quick Setup'!$N$33,'Quick Setup'!$N34,if(BF4='Quick Setup'!$O$33,'Quick Setup'!$O34,if(BF4='Quick Setup'!$P$33,'Quick Setup'!$P34,if(BF4='Quick Setup'!$Q$33,'Quick Setup'!$Q34,if(BF4='Quick Setup'!$R$33,'Quick Setup'!$R34,if(BF4='Quick Setup'!$S$33,'Quick Setup'!$S34,if(BF4='Quick Setup'!$T$33,'Quick Setup'!$T34,if(BF4='Quick Setup'!$U$33,'Quick Setup'!$U34,if(BF4='Quick Setup'!$V$33,'Quick Setup'!$V34,'2x'!CA5)))))))))))))))))))) -> 3 | BH4: =if(BF4='Quick Setup'!$C$47,'Quick Setup'!$C48,if(BF4='Quick Setup'!$D$47,'Quick Setup'!$D48,if(BF4='Quick Setup'!$E$47,'Quick Setup'!$E48,if(BF4='Quick Setup'!$F$47,'Quick Setup'!$F48,if(BF4='Quick Setup'!$G$47,'Quick Setup'!$G48,if(BF4='Quick Setup'!$H$47,'Quick Setup'!$H48,if(BF4='Quick Setup'!$I$47,'Quick Setup'!$I48,if(BF4='Quick Setup'!$J$47,'Quick Setup'!$J48,if(BF4='Quick Setup'!$K$47,'Quick Setup'!$K48,if(BF4='Quick Setup'!$L$47,'Quick Setup'!$L48,if(BF4='Quick Setup'!$M$47,'Quick Setup'!$M48,if(BF4='Quick Setup'!$N$47,'Quick Setup'!$N48,if(BF4='Quick Setup'!$O$47,'Quick Setup'!$O48,if(BF4='Quick Setup'!$P$47,'Quick Setup'!$P48,if(BF4='Quick Setup'!$Q$47,'Quick Setup'!$Q48,if(BF4='Quick Setup'!$R$47,'Quick Setup'!$R48,if(BF4='Quick Setup'!$S$47,'Quick Setup'!$S48,if(BF4='Quick Setup'!$T$47,'Quick Setup'!$T48,if(BF4='Quick Setup'!$U$47,'Quick Setup'!$U48,if(BF4='Quick Setup'!$V$47,'Quick Setup'!$V48,if(BF4='Quick Setup'!$W$47,'Quick Setup'!$W48))))))))))))))))))))) -> 2 | BI4: =BB4 -> 4 | BJ4: =BC4 -> 6 | BK4: =BD4 -> 0.02 | BL4: =BE4 -> -0.05 | BM4: ='Quick Setup'!L61 -> 0.85 | BN4: =if(BM4='Quick Setup'!$C$33,'Quick Setup'!$C34,if(BM4='Quick Setup'!$D$33,'Quick Setup'!$D34,if(BM4='Quick Setup'!$E$33,'Quick Setup'!$E34,if(BM4='Quick Setup'!$F$33,'Quick Setup'!$F34,if(BM4='Quick Setup'!$G$33,'Quick Setup'!$G34,if(BM4='Quick Setup'!$H$33,'Quick Setup'!$H34,if(BM4='Quick Setup'!$I$33,'Quick Setup'!$I34,if(BM4='Quick Setup'!$J$33,'Quick Setup'!$J34,if(BM4='Quick Setup'!$K$33,'Quick Setup'!$K34,if(BM4='Quick Setup'!$L$33,'Quick Setup'!$L34,if(BM4='Quick Setup'!$M$33,'Quick Setup'!$M34,if(BM4='Quick Setup'!$N$33,'Quick Setup'!$N34,if(BM4='Quick Setup'!$O$33,'Quick Setup'!$O34,if(BM4='Quick Setup'!$P$33,'Quick Setup'!$P34,if(BM4='Quick Setup'!$Q$33,'Quick Setup'!$Q34,if(BM4='Quick Setup'!$R$33,'Quick Setup'!$R34,if(BM4='Quick Setup'!$S$33,'Quick Setup'!$S34,if(BM4='Quick Setup'!$T$33,'Quick Setup'!$T34,if(BM4='Quick Setup'!$U$33,'Quick Setup'!$U34,if(BM4='Quick Setup'!$V$33,'Quick Setup'!$V34,'2x'!CH5)))))))))))))))))))) -> 2 | BO4: =if(BM4='Quick Setup'!$C$47,'Quick Setup'!$C48,if(BM4='Quick Setup'!$D$47,'Quick Setup'!$D48,if(BM4='Quick Setup'!$E$47,'Quick Setup'!$E48,if(BM4='Quick Setup'!$F$47,'Quick Setup'!$F48,if(BM4='Quick Setup'!$G$47,'Quick Setup'!$G48,if(BM4='Quick Setup'!$H$47,'Quick Setup'!$H48,if(BM4='Quick Setup'!$I$47,'Quick Setup'!$I48,if(BM4='Quick Setup'!$J$47,'Quick Setup'!$J48,if(BM4='Quick Setup'!$K$47,'Quick Setup'!$K48,if(BM4='Quick Setup'!$L$47,'Quick Setup'!$L48,if(BM4='Quick Setup'!$M$47,'Quick Setup'!$M48,if(BM4='Quick Setup'!$N$47,'Quick Setup'!$N48,if(BM4='Quick Setup'!$O$47,'Quick Setup'!$O48,if(BM4='Quick Setup'!$P$47,'Quick Setup'!$P48,if(BM4='Quick Setup'!$Q$47,'Quick Setup'!$Q48,if(BM4='Quick Setup'!$R$47,'Quick Setup'!$R48,if(BM4='Quick Setup'!$S$47,'Quick Setup'!$S48,if(BM4='Quick Setup'!$T$47,'Quick Setup'!$T48,if(BM4='Quick Setup'!$U$47,'Quick Setup'!$U48,if(BM4='Quick Setup'!$V$47,'Quick Setup'!$V48,if(BM4='Quick Setup'!$W$47,'Quick Setup'!$W48))))))))))))))))))))) -> 2 | BP4: =BI4 -> 4 | BQ4: =BJ4 -> 6 | BR4: =BK4 -> 0.02 | BS4: =BL4 -> -0.05 | BT4: ='Quick Setup'!M61 -> 0.775 | BU4: =if(BT4='Quick Setup'!$C$33,'Quick Setup'!$C34,if(BT4='Quick Setup'!$D$33,'Quick Setup'!$D34,if(BT4='Quick Setup'!$E$33,'Quick Setup'!$E34,if(BT4='Quick Setup'!$F$33,'Quick Setup'!$F34,if(BT4='Quick Setup'!$G$33,'Quick Setup'!$G34,if(BT4='Quick Setup'!$H$33,'Quick Setup'!$H34,if(BT4='Quick Setup'!$I$33,'Quick Setup'!$I34,if(BT4='Quick Setup'!$J$33,'Quick Setup'!$J34,if(BT4='Quick Setup'!$K$33,'Quick Setup'!$K34,if(BT4='Quick Setup'!$L$33,'Quick Setup'!$L34,if(BT4='Quick Setup'!$M$33,'Quick Setup'!$M34,if(BT4='Quick Setup'!$N$33,'Quick Setup'!$N34,if(BT4='Quick Setup'!$O$33,'Quick Setup'!$O34,if(BT4='Quick Setup'!$P$33,'Quick Setup'!$P34,if(BT4='Quick Setup'!$Q$33,'Quick Setup'!$Q34,if(BT4='Quick Setup'!$R$33,'Quick Setup'!$R34,if(BT4='Quick Setup'!$S$33,'Quick Setup'!$S34,if(BT4='Quick Setup'!$T$33,'Quick Setup'!$T34,if(BT4='Quick Setup'!$U$33,'Quick Setup'!$U34,if(BT4='Quick Setup'!$V$33,'Quick Setup'!$V34,'2x'!CO5)))))))))))))))))))) -> 4 | BV4: =if(BT4='Quick Setup'!$C$47,'Quick Setup'!$C48,if(BT4='Quick Setup'!$D$47,'Quick Setup'!$D48,if(BT4='Quick Setup'!$E$47,'Quick Setup'!$E48,if(BT4='Quick Setup'!$F$47,'Quick Setup'!$F48,if(BT4='Quick Setup'!$G$47,'Quick Setup'!$G48,if(BT4='Quick Setup'!$H$47,'Quick Setup'!$H48,if(BT4='Quick Setup'!$I$47,'Quick Setup'!$I48,if(BT4='Quick Setup'!$J$47,'Quick Setup'!$J48,if(BT4='Quick Setup'!$K$47,'Quick Setup'!$K48,if(BT4='Quick Setup'!$L$47,'Quick Setup'!$L48,if(BT4='Quick Setup'!$M$47,'Quick Setup'!$M48,if(BT4='Quick Setup'!$N$47,'Quick Setup'!$N48,if(BT4='Quick Setup'!$O$47,'Quick Setup'!$O48,if(BT4='Quick Setup'!$P$47,'Quick Setup'!$P48,if(BT4='Quick Setup'!$Q$47,'Quick Setup'!$Q48,if(BT4='Quick Setup'!$R$47,'Quick Setup'!$R48,if(BT4='Quick Setup'!$S$47,'Quick Setup'!$S48,if(BT4='Quick Setup'!$T$47,'Quick Setup'!$T48,if(BT4='Quick Setup'!$U$47,'Quick Setup'!$U48,if(BT4='Quick Setup'!$V$47,'Quick Setup'!$V48,if(BT4='Quick Setup'!$W$47,'Quick Setup'!$W48))))))))))))))))))))) -> 3 | BW4: =BP4 -> 4 | BX4: =BQ4 -> 6 | BY4: =BR4 -> 0.02 | BZ4: =BS4 -> -0.05 | CA4: ='Quick Setup'!N61 -> 0.825 | CB4: =if(CA4='Quick Setup'!$C$33,'Quick Setup'!$C34,if(CA4='Quick Setup'!$D$33,'Quick Setup'!$D34,if(CA4='Quick Setup'!$E$33,'Quick Setup'!$E34,if(CA4='Quick Setup'!$F$33,'Quick Setup'!$F34,if(CA4='Quick Setup'!$G$33,'Quick Setup'!$G34,if(CA4='Quick Setup'!$H$33,'Quick Setup'!$H34,if(CA4='Quick Setup'!$I$33,'Quick Setup'!$I34,if(CA4='Quick Setup'!$J$33,'Quick Setup'!$J34,if(CA4='Quick Setup'!$K$33,'Quick Setup'!$K34,if(CA4='Quick Setup'!$L$33,'Quick Setup'!$L34,if(CA4='Quick Setup'!$M$33,'Quick Setup'!$M34,if(CA4='Quick Setup'!$N$33,'Quick Setup'!$N34,if(CA4='Quick Setup'!$O$33,'Quick Setup'!$O34,if(CA4='Quick Setup'!$P$33,'Quick Setup'!$P34,if(CA4='Quick Setup'!$Q$33,'Quick Setup'!$Q34,if(CA4='Quick Setup'!$R$33,'Quick Setup'!$R34,if(CA4='Quick Setup'!$S$33,'Quick Setup'!$S34,if(CA4='Quick Setup'!$T$33,'Quick Setup'!$T34,if(CA4='Quick Setup'!$U$33,'Quick Setup'!$U34,if(CA4='Quick Setup'!$V$33,'Quick Setup'!$V34,'2x'!CV5)))))))))))))))))))) -> 3 | CC4: =if(CA4='Quick Setup'!$C$47,'Quick Setup'!$C48,if(CA4='Quick Setup'!$D$47,'Quick Setup'!$D48,if(CA4='Quick Setup'!$E$47,'Quick Setup'!$E48,if(CA4='Quick Setup'!$F$47,'Quick Setup'!$F48,if(CA4='Quick Setup'!$G$47,'Quick Setup'!$G48,if(CA4='Quick Setup'!$H$47,'Quick Setup'!$H48,if(CA4='Quick Setup'!$I$47,'Quick Setup'!$I48,if(CA4='Quick Setup'!$J$47,'Quick Setup'!$J48,if(CA4='Quick Setup'!$K$47,'Quick Setup'!$K48,if(CA4='Quick Setup'!$L$47,'Quick Setup'!$L48,if(CA4='Quick Setup'!$M$47,'Quick Setup'!$M48,if(CA4='Quick Setup'!$N$47,'Quick Setup'!$N48,if(CA4='Quick Setup'!$O$47,'Quick Setup'!$O48,if(CA4='Quick Setup'!$P$47,'Quick Setup'!$P48,if(CA4='Quick Setup'!$Q$47,'Quick Setup'!$Q48,if(CA4='Quick Setup'!$R$47,'Quick Setup'!$R48,if(CA4='Quick Setup'!$S$47,'Quick Setup'!$S48,if(CA4='Quick Setup'!$T$47,'Quick Setup'!$T48,if(CA4='Quick Setup'!$U$47,'Quick Setup'!$U48,if(CA4='Quick Setup'!$V$47,'Quick Setup'!$V48,if(CA4='Quick Setup'!$W$47,'Quick Setup'!$W48))))))))))))))))))))) -> 2 | CD4: =BW4 -> 4 | CE4: =BX4 -> 6 | CF4: =BY4 -> 0.02 | CG4: =BZ4 -> -0.05 | CH4: ='Quick Setup'!O61 -> 0.875 | CI4: =if(CH4='Quick Setup'!$C$33,'Quick Setup'!$C34,if(CH4='Quick Setup'!$D$33,'Quick Setup'!$D34,if(CH4='Quick Setup'!$E$33,'Quick Setup'!$E34,if(CH4='Quick Setup'!$F$33,'Quick Setup'!$F34,if(CH4='Quick Setup'!$G$33,'Quick Setup'!$G34,if(CH4='Quick Setup'!$H$33,'Quick Setup'!$H34,if(CH4='Quick Setup'!$I$33,'Quick Setup'!$I34,if(CH4='Quick Setup'!$J$33,'Quick Setup'!$J34,if(CH4='Quick Setup'!$K$33,'Quick Setup'!$K34,if(CH4='Quick Setup'!$L$33,'Quick Setup'!$L34,if(CH4='Quick Setup'!$M$33,'Quick Setup'!$M34,if(CH4='Quick Setup'!$N$33,'Quick Setup'!$N34,if(CH4='Quick Setup'!$O$33,'Quick Setup'!$O34,if(CH4='Quick Setup'!$P$33,'Quick Setup'!$P34,if(CH4='Quick Setup'!$Q$33,'Quick Setup'!$Q34,if(CH4='Quick Setup'!$R$33,'Quick Setup'!$R34,if(CH4='Quick Setup'!$S$33,'Quick Setup'!$S34,if(CH4='Quick Setup'!$T$33,'Quick Setup'!$T34,if(CH4='Quick Setup'!$U$33,'Quick Setup'!$U34,if(CH4='Quick Setup'!$V$33,'Quick Setup'!$V34,'2x'!DC5)))))))))))))))))))) -> 2 | CJ4: =if(CH4='Quick Setup'!$C$47,'Quick Setup'!$C48,if(CH4='Quick Setup'!$D$47,'Quick Setup'!$D48,if(CH4='Quick Setup'!$E$47,'Quick Setup'!$E48,if(CH4='Quick Setup'!$F$47,'Quick Setup'!$F48,if(CH4='Quick Setup'!$G$47,'Quick Setup'!$G48,if(CH4='Quick Setup'!$H$47,'Quick Setup'!$H48,if(CH4='Quick Setup'!$I$47,'Quick Setup'!$I48,if(CH4='Quick Setup'!$J$47,'Quick Setup'!$J48,if(CH4='Quick Setup'!$K$47,'Quick Setup'!$K48,if(CH4='Quick Setup'!$L$47,'Quick Setup'!$L48,if(CH4='Quick Setup'!$M$47,'Quick Setup'!$M48,if(CH4='Quick Setup'!$N$47,'Quick Setup'!$N48,if(CH4='Quick Setup'!$O$47,'Quick Setup'!$O48,if(CH4='Quick Setup'!$P$47,'Quick Setup'!$P48,if(CH4='Quick Setup'!$Q$47,'Quick Setup'!$Q48,if(CH4='Quick Setup'!$R$47,'Quick Setup'!$R48,if(CH4='Quick Setup'!$S$47,'Quick Setup'!$S48,if(CH4='Quick Setup'!$T$47,'Quick Setup'!$T48,if(CH4='Quick Setup'!$U$47,'Quick Setup'!$U48,if(CH4='Quick Setup'!$V$47,'Quick Setup'!$V48,if(CH4='Quick Setup'!$W$47,'Quick Setup'!$W48))))))))))))))))))))) -> 2 | CK4: =CD4 -> 4 | CL4: =CE4 -> 6 | CM4: =CF4 -> 0.02 | CN4: =CG4 -> -0.05 | CO4: ='Quick Setup'!P61 -> 0.6 | CP4: =if(CO4='Quick Setup'!$C$33,'Quick Setup'!$C34,if(CO4='Quick Setup'!$D$33,'Quick Setup'!$D34,if(CO4='Quick Setup'!$E$33,'Quick Setup'!$E34,if(CO4='Quick Setup'!$F$33,'Quick Setup'!$F34,if(CO4='Quick Setup'!$G$33,'Quick Setup'!$G34,if(CO4='Quick Setup'!$H$33,'Quick Setup'!$H34,if(CO4='Quick Setup'!$I$33,'Quick Setup'!$I34,if(CO4='Quick Setup'!$J$33,'Quick Setup'!$J34,if(CO4='Quick Setup'!$K$33,'Quick Setup'!$K34,if(CO4='Quick Setup'!$L$33,'Quick Setup'!$L34,if(CO4='Quick Setup'!$M$33,'Quick Setup'!$M34,if(CO4='Quick Setup'!$N$33,'Quick Setup'!$N34,if(CO4='Quick Setup'!$O$33,'Quick Setup'!$O34,if(CO4='Quick Setup'!$P$33,'Quick Setup'!$P34,if(CO4='Quick Setup'!$Q$33,'Quick Setup'!$Q34,if(CO4='Quick Setup'!$R$33,'Quick Setup'!$R34,if(CO4='Quick Setup'!$S$33,'Quick Setup'!$S34,if(CO4='Quick Setup'!$T$33,'Quick Setup'!$T34,if(CO4='Quick Setup'!$U$33,'Quick Setup'!$U34,if(CO4='Quick Setup'!$V$33,'Quick Setup'!$V34,'2x'!DJ5)))))))))))))))))))) -> 7 | CQ4: =if(CO4='Quick Setup'!$C$47,'Quick Setup'!$C48,if(CO4='Quick Setup'!$D$47,'Quick Setup'!$D48,if(CO4='Quick Setup'!$E$47,'Quick Setup'!$E48,if(CO4='Quick Setup'!$F$47,'Quick Setup'!$F48,if(CO4='Quick Setup'!$G$47,'Quick Setup'!$G48,if(CO4='Quick Setup'!$H$47,'Quick Setup'!$H48,if(CO4='Quick Setup'!$I$47,'Quick Setup'!$I48,if(CO4='Quick Setup'!$J$47,'Quick Setup'!$J48,if(CO4='Quick Setup'!$K$47,'Quick Setup'!$K48,if(CO4='Quick Setup'!$L$47,'Quick Setup'!$L48,if(CO4='Quick Setup'!$M$47,'Quick Setup'!$M48,if(CO4='Quick Setup'!$N$47,'Quick Setup'!$N48,if(CO4='Quick Setup'!$O$47,'Quick Setup'!$O48,if(CO4='Quick Setup'!$P$47,'Quick Setup'!$P48,if(CO4='Quick Setup'!$Q$47,'Quick Setup'!$Q48,if(CO4='Quick Setup'!$R$47,'Quick Setup'!$R48,if(CO4='Quick Setup'!$S$47,'Quick Setup'!$S48,if(CO4='Quick Setup'!$T$47,'Quick Setup'!$T48,if(CO4='Quick Setup'!$U$47,'Quick Setup'!$U48,if(CO4='Quick Setup'!$V$47,'Quick Setup'!$V48,if(CO4='Quick Setup'!$W$47,'Quick Setup'!$W48))))))))))))))))))))) -> 4 | CR4: =CK4 -> 4 | CS4: =CL4 -> 6 | CT4: =CM4 -> 0.02 | CU4: =CN4 -> -0.05 | CV4: ='Quick Setup'!Q61 -> 0.8 | CW4: =if(CV4='Quick Setup'!$C$33,'Quick Setup'!$C34,if(CV4='Quick Setup'!$D$33,'Quick Setup'!$D34,if(CV4='Quick Setup'!$E$33,'Quick Setup'!$E34,if(CV4='Quick Setup'!$F$33,'Quick Setup'!$F34,if(CV4='Quick Setup'!$G$33,'Quick Setup'!$G34,if(CV4='Quick Setup'!$H$33,'Quick Setup'!$H34,if(CV4='Quick Setup'!$I$33,'Quick Setup'!$I34,if(CV4='Quick Setup'!$J$33,'Quick Setup'!$J34,if(CV4='Quick Setup'!$K$33,'Quick Setup'!$K34,if(CV4='Quick Setup'!$L$33,'Quick Setup'!$L34,if(CV4='Quick Setup'!$M$33,'Quick Setup'!$M34,if(CV4='Quick Setup'!$N$33,'Quick Setup'!$N34,if(CV4='Quick Setup'!$O$33,'Quick Setup'!$O34,if(CV4='Quick Setup'!$P$33,'Quick Setup'!$P34,if(CV4='Quick Setup'!$Q$33,'Quick Setup'!$Q34,if(CV4='Quick Setup'!$R$33,'Quick Setup'!$R34,if(CV4='Quick Setup'!$S$33,'Quick Setup'!$S34,if(CV4='Quick Setup'!$T$33,'Quick Setup'!$T34,if(CV4='Quick Setup'!$U$33,'Quick Setup'!$U34,if(CV4='Quick Setup'!$V$33,'Quick Setup'!$V34,'2x'!DQ5)))))))))))))))))))) -> 3 | CX4: =if(CV4='Quick Setup'!$C$47,'Quick Setup'!$C48,if(CV4='Quick Setup'!$D$47,'Quick Setup'!$D48,if(CV4='Quick Setup'!$E$47,'Quick Setup'!$E48,if(CV4='Quick Setup'!$F$47,'Quick Setup'!$F48,if(CV4='Quick Setup'!$G$47,'Quick Setup'!$G48,if(CV4='Quick Setup'!$H$47,'Quick Setup'!$H48,if(CV4='Quick Setup'!$I$47,'Quick Setup'!$I48,if(CV4='Quick Setup'!$J$47,'Quick Setup'!$J48,if(CV4='Quick Setup'!$K$47,'Quick Setup'!$K48,if(CV4='Quick Setup'!$L$47,'Quick Setup'!$L48,if(CV4='Quick Setup'!$M$47,'Quick Setup'!$M48,if(CV4='Quick Setup'!$N$47,'Quick Setup'!$N48,if(CV4='Quick Setup'!$O$47,'Quick Setup'!$O48,if(CV4='Quick Setup'!$P$47,'Quick Setup'!$P48,if(CV4='Quick Setup'!$Q$47,'Quick Setup'!$Q48,if(CV4='Quick Setup'!$R$47,'Quick Setup'!$R48,if(CV4='Quick Setup'!$S$47,'Quick Setup'!$S48,if(CV4='Quick Setup'!$T$47,'Quick Setup'!$T48,if(CV4='Quick Setup'!$U$47,'Quick Setup'!$U48,if(CV4='Quick Setup'!$V$47,'Quick Setup'!$V48,if(CV4='Quick Setup'!$W$47,'Quick Setup'!$W48))))))))))))))))))))) -> 2 | CY4: =CR4 -> 4 | CZ4: =CS4 -> 6 | DA4: =CT4 -> 0.02 | DB4: =CU4 -> -0.05 | DC4: ='Quick Setup'!R61 -> 0.85 | DD4: =if(DC4='Quick Setup'!$C$33,'Quick Setup'!$C34,if(DC4='Quick Setup'!$D$33,'Quick Setup'!$D34,if(DC4='Quick Setup'!$E$33,'Quick Setup'!$E34,if(DC4='Quick Setup'!$F$33,'Quick Setup'!$F34,if(DC4='Quick Setup'!$G$33,'Quick Setup'!$G34,if(DC4='Quick Setup'!$H$33,'Quick Setup'!$H34,if(DC4='Quick Setup'!$I$33,'Quick Setup'!$I34,if(DC4='Quick Setup'!$J$33,'Quick Setup'!$J34,if(DC4='Quick Setup'!$K$33,'Quick Setup'!$K34,if(DC4='Quick Setup'!$L$33,'Quick Setup'!$L34,if(DC4='Quick Setup'!$M$33,'Quick Setup'!$M34,if(DC4='Quick Setup'!$N$33,'Quick Setup'!$N34,if(DC4='Quick Setup'!$O$33,'Quick Setup'!$O34,if(DC4='Quick Setup'!$P$33,'Quick Setup'!$P34,if(DC4='Quick Setup'!$Q$33,'Quick Setup'!$Q34,if(DC4='Quick Setup'!$R$33,'Quick Setup'!$R34,if(DC4='Quick Setup'!$S$33,'Quick Setup'!$S34,if(DC4='Quick Setup'!$T$33,'Quick Setup'!$T34,if(DC4='Quick Setup'!$U$33,'Quick Setup'!$U34,if(DC4='Quick Setup'!$V$33,'Quick Setup'!$V34,'2x'!DX5)))))))))))))))))))) -> 2 | DE4: =if(DC4='Quick Setup'!$C$47,'Quick Setup'!$C48,if(DC4='Quick Setup'!$D$47,'Quick Setup'!$D48,if(DC4='Quick Setup'!$E$47,'Quick Setup'!$E48,if(DC4='Quick Setup'!$F$47,'Quick Setup'!$F48,if(DC4='Quick Setup'!$G$47,'Quick Setup'!$G48,if(DC4='Quick Setup'!$H$47,'Quick Setup'!$H48,if(DC4='Quick Setup'!$I$47,'Quick Setup'!$I48,if(DC4='Quick Setup'!$J$47,'Quick Setup'!$J48,if(DC4='Quick Setup'!$K$47,'Quick Setup'!$K48,if(DC4='Quick Setup'!$L$47,'Quick Setup'!$L48,if(DC4='Quick Setup'!$M$47,'Quick Setup'!$M48,if(DC4='Quick Setup'!$N$47,'Quick Setup'!$N48,if(DC4='Quick Setup'!$O$47,'Quick Setup'!$O48,if(DC4='Quick Setup'!$P$47,'Quick Setup'!$P48,if(DC4='Quick Setup'!$Q$47,'Quick Setup'!$Q48,if(DC4='Quick Setup'!$R$47,'Quick Setup'!$R48,if(DC4='Quick Setup'!$S$47,'Quick Setup'!$S48,if(DC4='Quick Setup'!$T$47,'Quick Setup'!$T48,if(DC4='Quick Setup'!$U$47,'Quick Setup'!$U48,if(DC4='Quick Setup'!$V$47,'Quick Setup'!$V48,if(DC4='Quick Setup'!$W$47,'Quick Setup'!$W48))))))))))))))))))))) -> 2 | DF4: =CY4 -> 4 | DG4: =CZ4 -> 6 | DH4: =DA4 -> 0.02 | DI4: =DB4 -> -0.05 | DJ4: ='Quick Setup'!S61 -> 0.9 | DK4: =if(DJ4='Quick Setup'!$C$33,'Quick Setup'!$C34,if(DJ4='Quick Setup'!$D$33,'Quick Setup'!$D34,if(DJ4='Quick Setup'!$E$33,'Quick Setup'!$E34,if(DJ4='Quick Setup'!$F$33,'Quick Setup'!$F34,if(DJ4='Quick Setup'!$G$33,'Quick Setup'!$G34,if(DJ4='Quick Setup'!$H$33,'Quick Setup'!$H34,if(DJ4='Quick Setup'!$I$33,'Quick Setup'!$I34,if(DJ4='Quick Setup'!$J$33,'Quick Setup'!$J34,if(DJ4='Quick Setup'!$K$33,'Quick Setup'!$K34,if(DJ4='Quick Setup'!$L$33,'Quick Setup'!$L34,if(DJ4='Quick Setup'!$M$33,'Quick Setup'!$M34,if(DJ4='Quick Setup'!$N$33,'Quick Setup'!$N34,if(DJ4='Quick Setup'!$O$33,'Quick Setup'!$O34,if(DJ4='Quick Setup'!$P$33,'Quick Setup'!$P34,if(DJ4='Quick Setup'!$Q$33,'Quick Setup'!$Q34,if(DJ4='Quick Setup'!$R$33,'Quick Setup'!$R34,if(DJ4='Quick Setup'!$S$33,'Quick Setup'!$S34,if(DJ4='Quick Setup'!$T$33,'Quick Setup'!$T34,if(DJ4='Quick Setup'!$U$33,'Quick Setup'!$U34,if(DJ4='Quick Setup'!$V$33,'Quick Setup'!$V34,'2x'!EE5)))))))))))))))))))) -> 1 | DL4: =if(DJ4='Quick Setup'!$C$47,'Quick Setup'!$C48,if(DJ4='Quick Setup'!$D$47,'Quick Setup'!$D48,if(DJ4='Quick Setup'!$E$47,'Quick Setup'!$E48,if(DJ4='Quick Setup'!$F$47,'Quick Setup'!$F48,if(DJ4='Quick Setup'!$G$47,'Quick Setup'!$G48,if(DJ4='Quick Setup'!$H$47,'Quick Setup'!$H48,if(DJ4='Quick Setup'!$I$47,'Quick Setup'!$I48,if(DJ4='Quick Setup'!$J$47,'Quick Setup'!$J48,if(DJ4='Quick Setup'!$K$47,'Quick Setup'!$K48,if(DJ4='Quick Setup'!$L$47,'Quick Setup'!$L48,if(DJ4='Quick Setup'!$M$47,'Quick Setup'!$M48,if(DJ4='Quick Setup'!$N$47,'Quick Setup'!$N48,if(DJ4='Quick Setup'!$O$47,'Quick Setup'!$O48,if(DJ4='Quick Setup'!$P$47,'Quick Setup'!$P48,if(DJ4='Quick Setup'!$Q$47,'Quick Setup'!$Q48,if(DJ4='Quick Setup'!$R$47,'Quick Setup'!$R48,if(DJ4='Quick Setup'!$S$47,'Quick Setup'!$S48,if(DJ4='Quick Setup'!$T$47,'Quick Setup'!$T48,if(DJ4='Quick Setup'!$U$47,'Quick Setup'!$U48,if(DJ4='Quick Setup'!$V$47,'Quick Setup'!$V48,if(DJ4='Quick Setup'!$W$47,'Quick Setup'!$W48))))))))))))))))))))) -> 1 | DM4: =DF4 -> 4 | DN4: =DG4 -> 6 | DO4: =DH4 -> 0.02 | DP4: =DI4 -> -0.05 | DQ4: ='Quick Setup'!T61 -> 0.85 | DR4: =if(DQ4='Quick Setup'!$C$33,'Quick Setup'!$C34,if(DQ4='Quick Setup'!$D$33,'Quick Setup'!$D34,if(DQ4='Quick Setup'!$E$33,'Quick Setup'!$E34,if(DQ4='Quick Setup'!$F$33,'Quick Setup'!$F34,if(DQ4='Quick Setup'!$G$33,'Quick Setup'!$G34,if(DQ4='Quick Setup'!$H$33,'Quick Setup'!$H34,if(DQ4='Quick Setup'!$I$33,'Quick Setup'!$I34,if(DQ4='Quick Setup'!$J$33,'Quick Setup'!$J34,if(DQ4='Quick Setup'!$K$33,'Quick Setup'!$K34,if(DQ4='Quick Setup'!$L$33,'Quick Setup'!$L34,if(DQ4='Quick Setup'!$M$33,'Quick Setup'!$M34,if(DQ4='Quick Setup'!$N$33,'Quick Setup'!$N34,if(DQ4='Quick Setup'!$O$33,'Quick Setup'!$O34,if(DQ4='Quick Setup'!$P$33,'Quick Setup'!$P34,if(DQ4='Quick Setup'!$Q$33,'Quick Setup'!$Q34,if(DQ4='Quick Setup'!$R$33,'Quick Setup'!$R34,if(DQ4='Quick Setup'!$S$33,'Quick Setup'!$S34,if(DQ4='Quick Setup'!$T$33,'Quick Setup'!$T34,if(DQ4='Quick Setup'!$U$33,'Quick Setup'!$U34,if(DQ4='Quick Setup'!$V$33,'Quick Setup'!$V34,'2x'!EL5)))))))))))))))))))) -> 2 | DS4: =if(DQ4='Quick Setup'!$C$47,'Quick Setup'!$C48,if(DQ4='Quick Setup'!$D$47,'Quick Setup'!$D48,if(DQ4='Quick Setup'!$E$47,'Quick Setup'!$E48,if(DQ4='Quick Setup'!$F$47,'Quick Setup'!$F48,if(DQ4='Quick Setup'!$G$47,'Quick Setup'!$G48,if(DQ4='Quick Setup'!$H$47,'Quick Setup'!$H48,if(DQ4='Quick Setup'!$I$47,'Quick Setup'!$I48,if(DQ4='Quick Setup'!$J$47,'Quick Setup'!$J48,if(DQ4='Quick Setup'!$K$47,'Quick Setup'!$K48,if(DQ4='Quick Setup'!$L$47,'Quick Setup'!$L48,if(DQ4='Quick Setup'!$M$47,'Quick Setup'!$M48,if(DQ4='Quick Setup'!$N$47,'Quick Setup'!$N48,if(DQ4='Quick Setup'!$O$47,'Quick Setup'!$O48,if(DQ4='Quick Setup'!$P$47,'Quick Setup'!$P48,if(DQ4='Quick Setup'!$Q$47,'Quick Setup'!$Q48,if(DQ4='Quick Setup'!$R$47,'Quick Setup'!$R48,if(DQ4='Quick Setup'!$S$47,'Quick Setup'!$S48,if(DQ4='Quick Setup'!$T$47,'Quick Setup'!$T48,if(DQ4='Quick Setup'!$U$47,'Quick Setup'!$U48,if(DQ4='Quick Setup'!$V$47,'Quick Setup'!$V48,if(DQ4='Quick Setup'!$W$47,'Quick Setup'!$W48))))))))))))))))))))) -> 2 | DT4: =DM4 -> 4 | DU4: =DN4 -> 6 | DV4: =DO4 -> 0.02 | DW4: =DP4 -> -0.05 | DX4: ='Quick Setup'!U61 -> 0.9 | DY4: =if(DX4='Quick Setup'!$C$33,'Quick Setup'!$C34,if(DX4='Quick Setup'!$D$33,'Quick Setup'!$D34,if(DX4='Quick Setup'!$E$33,'Quick Setup'!$E34,if(DX4='Quick Setup'!$F$33,'Quick Setup'!$F34,if(DX4='Quick Setup'!$G$33,'Quick Setup'!$G34,if(DX4='Quick Setup'!$H$33,'Quick Setup'!$H34,if(DX4='Quick Setup'!$I$33,'Quick Setup'!$I34,if(DX4='Quick Setup'!$J$33,'Quick Setup'!$J34,if(DX4='Quick Setup'!$K$33,'Quick Setup'!$K34,if(DX4='Quick Setup'!$L$33,'Quick Setup'!$L34,if(DX4='Quick Setup'!$M$33,'Quick Setup'!$M34,if(DX4='Quick Setup'!$N$33,'Quick Setup'!$N34,if(DX4='Quick Setup'!$O$33,'Quick Setup'!$O34,if(DX4='Quick Setup'!$P$33,'Quick Setup'!$P34,if(DX4='Quick Setup'!$Q$33,'Quick Setup'!$Q34,if(DX4='Quick Setup'!$R$33,'Quick Setup'!$R34,if(DX4='Quick Setup'!$S$33,'Quick Setup'!$S34,if(DX4='Quick Setup'!$T$33,'Quick Setup'!$T34,if(DX4='Quick Setup'!$U$33,'Quick Setup'!$U34,if(DX4='Quick Setup'!$V$33,'Quick Setup'!$V34,'2x'!ES5)))))))))))))))))))) -> 1 | DZ4: =if(DX4='Quick Setup'!$C$47,'Quick Setup'!$C48,if(DX4='Quick Setup'!$D$47,'Quick Setup'!$D48,if(DX4='Quick Setup'!$E$47,'Quick Setup'!$E48,if(DX4='Quick Setup'!$F$47,'Quick Setup'!$F48,if(DX4='Quick Setup'!$G$47,'Quick Setup'!$G48,if(DX4='Quick Setup'!$H$47,'Quick Setup'!$H48,if(DX4='Quick Setup'!$I$47,'Quick Setup'!$I48,if(DX4='Quick Setup'!$J$47,'Quick Setup'!$J48,if(DX4='Quick Setup'!$K$47,'Quick Setup'!$K48,if(DX4='Quick Setup'!$L$47,'Quick Setup'!$L48,if(DX4='Quick Setup'!$M$47,'Quick Setup'!$M48,if(DX4='Quick Setup'!$N$47,'Quick Setup'!$N48,if(DX4='Quick Setup'!$O$47,'Quick Setup'!$O48,if(DX4='Quick Setup'!$P$47,'Quick Setup'!$P48,if(DX4='Quick Setup'!$Q$47,'Quick Setup'!$Q48,if(DX4='Quick Setup'!$R$47,'Quick Setup'!$R48,if(DX4='Quick Setup'!$S$47,'Quick Setup'!$S48,if(DX4='Quick Setup'!$T$47,'Quick Setup'!$T48,if(DX4='Quick Setup'!$U$47,'Quick Setup'!$U48,if(DX4='Quick Setup'!$V$47,'Quick Setup'!$V48,if(DX4='Quick Setup'!$W$47,'Quick Setup'!$W48))))))))))))))))))))) -> 1 | EA4: =DT4 -> 4 | EB4: =DU4 -> 6 | EC4: =DV4 -> 0.02 | ED4: =DW4 -> -0.05 | EE4: ='Quick Setup'!V61 -> 0.95 | EF4: =if(EE4='Quick Setup'!$C$33,'Quick Setup'!$C34,if(EE4='Quick Setup'!$D$33,'Quick Setup'!$D34,if(EE4='Quick Setup'!$E$33,'Quick Setup'!$E34,if(EE4='Quick Setup'!$F$33,'Quick Setup'!$F34,if(EE4='Quick Setup'!$G$33,'Quick Setup'!$G34,if(EE4='Quick Setup'!$H$33,'Quick Setup'!$H34,if(EE4='Quick Setup'!$I$33,'Quick Setup'!$I34,if(EE4='Quick Setup'!$J$33,'Quick Setup'!$J34,if(EE4='Quick Setup'!$K$33,'Quick Setup'!$K34,if(EE4='Quick Setup'!$L$33,'Quick Setup'!$L34,if(EE4='Quick Setup'!$M$33,'Quick Setup'!$M34,if(EE4='Quick Setup'!$N$33,'Quick Setup'!$N34,if(EE4='Quick Setup'!$O$33,'Quick Setup'!$O34,if(EE4='Quick Setup'!$P$33,'Quick Setup'!$P34,if(EE4='Quick Setup'!$Q$33,'Quick Setup'!$Q34,if(EE4='Quick Setup'!$R$33,'Quick Setup'!$R34,if(EE4='Quick Setup'!$S$33,'Quick Setup'!$S34,if(EE4='Quick Setup'!$T$33,'Quick Setup'!$T34,if(EE4='Quick Setup'!$U$33,'Quick Setup'!$U34,if(EE4='Quick Setup'!$V$33,'Quick Setup'!$V34,'2x'!EZ5)))))))))))))))))))) -> 1 | EG4: =if(EE4='Quick Setup'!$C$47,'Quick Setup'!$C48,if(EE4='Quick Setup'!$D$47,'Quick Setup'!$D48,if(EE4='Quick Setup'!$E$47,'Quick Setup'!$E48,if(EE4='Quick Setup'!$F$47,'Quick Setup'!$F48,if(EE4='Quick Setup'!$G$47,'Quick Setup'!$G48,if(EE4='Quick Setup'!$H$47,'Quick Setup'!$H48,if(EE4='Quick Setup'!$I$47,'Quick Setup'!$I48,if(EE4='Quick Setup'!$J$47,'Quick Setup'!$J48,if(EE4='Quick Setup'!$K$47,'Quick Setup'!$K48,if(EE4='Quick Setup'!$L$47,'Quick Setup'!$L48,if(EE4='Quick Setup'!$M$47,'Quick Setup'!$M48,if(EE4='Quick Setup'!$N$47,'Quick Setup'!$N48,if(EE4='Quick Setup'!$O$47,'Quick Setup'!$O48,if(EE4='Quick Setup'!$P$47,'Quick Setup'!$P48,if(EE4='Quick Setup'!$Q$47,'Quick Setup'!$Q48,if(EE4='Quick Setup'!$R$47,'Quick Setup'!$R48,if(EE4='Quick Setup'!$S$47,'Quick Setup'!$S48,if(EE4='Quick Setup'!$T$47,'Quick Setup'!$T48,if(EE4='Quick Setup'!$U$47,'Quick Setup'!$U48,if(EE4='Quick Setup'!$V$47,'Quick Setup'!$V48,if(EE4='Quick Setup'!$W$47,'Quick Setup'!$W48))))))))))))))))))))) -> 1 | EH4: =EA4 -> 4 | EI4: =EB4 -> 6 | EJ4: =EC4 -> 0.02 | EK4: =ED4 -> -0.05 | EL4: ='Quick Setup'!W61 -> 0.6 | EM4: =if(EL4='Quick Setup'!$C$33,'Quick Setup'!$C34,if(EL4='Quick Setup'!$D$33,'Quick Setup'!$D34,if(EL4='Quick Setup'!$E$33,'Quick Setup'!$E34,if(EL4='Quick Setup'!$F$33,'Quick Setup'!$F34,if(EL4='Quick Setup'!$G$33,'Quick Setup'!$G34,if(EL4='Quick Setup'!$H$33,'Quick Setup'!$H34,if(EL4='Quick Setup'!$I$33,'Quick Setup'!$I34,if(EL4='Quick Setup'!$J$33,'Quick Setup'!$J34,if(EL4='Quick Setup'!$K$33,'Quick Setup'!$K34,if(EL4='Quick Setup'!$L$33,'Quick Setup'!$L34,if(EL4='Quick Setup'!$M$33,'Quick Setup'!$M34,if(EL4='Quick Setup'!$N$33,'Quick Setup'!$N34,if(EL4='Quick Setup'!$O$33,'Quick Setup'!$O34,if(EL4='Quick Setup'!$P$33,'Quick Setup'!$P34,if(EL4='Quick Setup'!$Q$33,'Quick Setup'!$Q34,if(EL4='Quick Setup'!$R$33,'Quick Setup'!$R34,if(EL4='Quick Setup'!$S$33,'Quick Setup'!$S34,if(EL4='Quick Setup'!$T$33,'Quick Setup'!$T34,if(EL4='Quick Setup'!$U$33,'Quick Setup'!$U34,if(EL4='Quick Setup'!$V$33,'Quick Setup'!$V34,'2x'!FG5)))))))))))))))))))) -> 7 | EN4: =if(EL4='Quick Setup'!$C$47,'Quick Setup'!$C48,if(EL4='Quick Setup'!$D$47,'Quick Setup'!$D48,if(EL4='Quick Setup'!$E$47,'Quick Setup'!$E48,if(EL4='Quick Setup'!$F$47,'Quick Setup'!$F48,if(EL4='Quick Setup'!$G$47,'Quick Setup'!$G48,if(EL4='Quick Setup'!$H$47,'Quick Setup'!$H48,if(EL4='Quick Setup'!$I$47,'Quick Setup'!$I48,if(EL4='Quick Setup'!$J$47,'Quick Setup'!$J48,if(EL4='Quick Setup'!$K$47,'Quick Setup'!$K48,if(EL4='Quick Setup'!$L$47,'Quick Setup'!$L48,if(EL4='Quick Setup'!$M$47,'Quick Setup'!$M48,if(EL4='Quick Setup'!$N$47,'Quick Setup'!$N48,if(EL4='Quick Setup'!$O$47,'Quick Setup'!$O48,if(EL4='Quick Setup'!$P$47,'Quick Setup'!$P48,if(EL4='Quick Setup'!$Q$47,'Quick Setup'!$Q48,if(EL4='Quick Setup'!$R$47,'Quick Setup'!$R48,if(EL4='Quick Setup'!$S$47,'Quick Setup'!$S48,if(EL4='Quick Setup'!$T$47,'Quick Setup'!$T48,if(EL4='Quick Setup'!$U$47,'Quick Setup'!$U48,if(EL4='Quick Setup'!$V$47,'Quick Setup'!$V48,if(EL4='Quick Setup'!$W$47,'Quick Setup'!$W48))))))))))))))))))))) -> 4 | EO4: =EH4 -> 4 | EP4: =EI4 -> 6 | EQ4: =EJ4 -> 0.02 | ER4: =EK4 -> -0.05
